2025-09-24 17:32:04,346: /home/snapaibackend/snapAI-backend/api/views.py: Error [AnalyzePhoto]: unable to guess serializer. This is graceful fallback handling for APIViews. Consider using GenericAPIView as view base class, if view is under your control. Either way you may want to add a serializer_class (or method). Ignoring view for now.
2025-09-24 17:32:04,375: /home/snapaibackend/snapAI-backend/api/views.py: Error [ResendOTPView]: unable to guess serializer. This is graceful fallback handling for APIViews. Consider using GenericAPIView as view base class, if view is under your control. Either way you may want to add a serializer_class (or method). Ignoring view for now.
2025-09-24 17:32:04,419: /home/snapaibackend/snapAI-backend/api/views.py: Warning [MealViewSet]: Failed to obtain model through view's queryset due to raised exception. Prevent this either by setting "queryset = Model.objects.none()" on the view, checking for "getattr(self, "swagger_fake_view", False)" in get_queryset() or by simply using @extend_schema. (Exception: Field 'id' expected a number but got <django.contrib.auth.models.AnonymousUser object at 0x7e6f596ad5b0>.)
2025-09-24 17:32:04,377: /home/snapaibackend/snapAI-backend/api/views.py: Error [StartSignupView]: unable to guess serializer. This is graceful fallback handling for APIViews. Consider using GenericAPIView as view base class, if view is under your control. Either way you may want to add a serializer_class (or method). Ignoring view for now.
2025-09-24 17:32:04,378: /home/snapaibackend/snapAI-backend/api/views.py: Error [VerifySignupView]: unable to guess serializer. This is graceful fallback handling for APIViews. Consider using GenericAPIView as view base class, if view is under your control. Either way you may want to add a serializer_class (or method). Ignoring view for now.
2025-09-24 17:32:04,490: /home/snapaibackend/snapAI-backend/api/views.py: Warning [RatingViewSet]: Failed to obtain model through view's queryset due to raised exception. Prevent this either by setting "queryset = Model.objects.none()" on the view, checking for "getattr(self, "swagger_fake_view", False)" in get_queryset() or by simply using @extend_schema. (Exception: Field 'id' expected a number but got <django.contrib.auth.models.AnonymousUser object at 0x7e6f596ad5b0>.)
2025-09-24 17:32:04,494: /home/snapaibackend/snapAI-backend/api/views.py: Warning [RatingViewSet]: could not derive type of path parameter "id" because it is untyped and obtaining queryset from the viewset failed. Consider adding a type to the path (e.g. <int:id>) or annotating the parameter type with @extend_schema. Defaulting to "string".
2025-09-24 17:32:04,444: /home/snapaibackend/snapAI-backend/api/views.py: Warning [MealViewSet]: could not derive type of path parameter "id" because it is untyped and obtaining queryset from the viewset failed. Consider adding a type to the path (e.g. <int:id>) or annotating the parameter type with @extend_schema. Defaulting to "string".
2025-09-24 17:32:04,460: /home/snapaibackend/snapAI-backend/api/views.py: Warning [PlanViewSet]: Failed to obtain model through view's queryset due to raised exception. Prevent this either by setting "queryset = Model.objects.none()" on the view, checking for "getattr(self, "swagger_fake_view", False)" in get_queryset() or by simply using @extend_schema. (Exception: Field 'id' expected a number but got <django.contrib.auth.models.AnonymousUser object at 0x7e6f596ad5b0>.)
2025-09-24 17:32:04,467: /home/snapaibackend/snapAI-backend/api/views.py: Warning [PlanViewSet]: could not derive type of path parameter "id" because it is untyped and obtaining queryset from the viewset failed. Consider adding a type to the path (e.g. <int:id>) or annotating the parameter type with @extend_schema. Defaulting to "string".
2025-09-24 17:32:04,468: /home/snapaibackend/snapAI-backend/api/views.py: Warning [ProfileViewSet]: could not derive type of path parameter "id" because it is untyped and obtaining queryset from the viewset failed. Consider adding a type to the path (e.g. <int:id>) or annotating the parameter type with @extend_schema. Defaulting to "string".
2025-09-25 06:21:04,680: /home/snapaibackend/snapAI-backend/api/views.py: Error [AnalyzePhoto]: unable to guess serializer. This is graceful fallback handling for APIViews. Consider using GenericAPIView as view base class, if view is under your control. Either way you may want to add a serializer_class (or method). Ignoring view for now.
2025-09-25 06:21:04,726: /home/snapaibackend/snapAI-backend/api/views.py: Error [ResendOTPView]: unable to guess serializer. This is graceful fallback handling for APIViews. Consider using GenericAPIView as view base class, if view is under your control. Either way you may want to add a serializer_class (or method). Ignoring view for now.
2025-09-25 06:21:04,727: /home/snapaibackend/snapAI-backend/api/views.py: Error [StartSignupView]: unable to guess serializer. This is graceful fallback handling for APIViews. Consider using GenericAPIView as view base class, if view is under your control. Either way you may want to add a serializer_class (or method). Ignoring view for now.
2025-09-25 06:21:04,728: /home/snapaibackend/snapAI-backend/api/views.py: Error [VerifySignupView]: unable to guess serializer. This is graceful fallback handling for APIViews. Consider using GenericAPIView as view base class, if view is under your control. Either way you may want to add a serializer_class (or method). Ignoring view for now.
2025-09-25 06:21:04,772: /home/snapaibackend/snapAI-backend/api/views.py: Warning [MealViewSet]: Failed to obtain model through view's queryset due to raised exception. Prevent this either by setting "queryset = Model.objects.none()" on the view, checking for "getattr(self, "swagger_fake_view", False)" in get_queryset() or by simply using @extend_schema. (Exception: Field 'id' expected a number but got <django.contrib.auth.models.AnonymousUser object at 0x7e6f595796a0>.)
2025-09-25 06:21:04,809: /home/snapaibackend/snapAI-backend/api/views.py: Warning [MealViewSet]: could not derive type of path parameter "id" because it is untyped and obtaining queryset from the viewset failed. Consider adding a type to the path (e.g. <int:id>) or annotating the parameter type with @extend_schema. Defaulting to "string".
2025-09-25 06:21:04,824: /home/snapaibackend/snapAI-backend/api/views.py: Warning [PlanViewSet]: Failed to obtain model through view's queryset due to raised exception. Prevent this either by setting "queryset = Model.objects.none()" on the view, checking for "getattr(self, "swagger_fake_view", False)" in get_queryset() or by simply using @extend_schema. (Exception: Field 'id' expected a number but got <django.contrib.auth.models.AnonymousUser object at 0x7e6f595796a0>.)
2025-09-25 06:21:04,828: /home/snapaibackend/snapAI-backend/api/views.py: Warning [PlanViewSet]: could not derive type of path parameter "id" because it is untyped and obtaining queryset from the viewset failed. Consider adding a type to the path (e.g. <int:id>) or annotating the parameter type with @extend_schema. Defaulting to "string".
2025-09-25 06:21:04,829: /home/snapaibackend/snapAI-backend/api/views.py: Warning [ProfileViewSet]: could not derive type of path parameter "id" because it is untyped and obtaining queryset from the viewset failed. Consider adding a type to the path (e.g. <int:id>) or annotating the parameter type with @extend_schema. Defaulting to "string".
2025-09-25 06:21:04,857: /home/snapaibackend/snapAI-backend/api/views.py: Warning [RatingViewSet]: Failed to obtain model through view's queryset due to raised exception. Prevent this either by setting "queryset = Model.objects.none()" on the view, checking for "getattr(self, "swagger_fake_view", False)" in get_queryset() or by simply using @extend_schema. (Exception: Field 'id' expected a number but got <django.contrib.auth.models.AnonymousUser object at 0x7e6f595796a0>.)
2025-09-25 06:21:04,861: /home/snapaibackend/snapAI-backend/api/views.py: Warning [RatingViewSet]: could not derive type of path parameter "id" because it is untyped and obtaining queryset from the viewset failed. Consider adding a type to the path (e.g. <int:id>) or annotating the parameter type with @extend_schema. Defaulting to "string".
2025-09-25 07:27:36,324: Not Found: /
2025-09-25 07:27:38,842: /home/snapaibackend/snapAI-backend/api/views.py: Error [AnalyzePhoto]: unable to guess serializer. This is graceful fallback handling for APIViews. Consider using GenericAPIView as view base class, if view is under your control. Either way you may want to add a serializer_class (or method). Ignoring view for now.
2025-09-25 07:27:38,859: /home/snapaibackend/snapAI-backend/api/views.py: Error [ResendOTPView]: unable to guess serializer. This is graceful fallback handling for APIViews. Consider using GenericAPIView as view base class, if view is under your control. Either way you may want to add a serializer_class (or method). Ignoring view for now.
2025-09-25 07:27:38,861: /home/snapaibackend/snapAI-backend/api/views.py: Error [StartSignupView]: unable to guess serializer. This is graceful fallback handling for APIViews. Consider using GenericAPIView as view base class, if view is under your control. Either way you may want to add a serializer_class (or method). Ignoring view for now.
2025-09-25 07:27:38,863: /home/snapaibackend/snapAI-backend/api/views.py: Error [VerifySignupView]: unable to guess serializer. This is graceful fallback handling for APIViews. Consider using GenericAPIView as view base class, if view is under your control. Either way you may want to add a serializer_class (or method). Ignoring view for now.
2025-09-25 07:27:38,873: /home/snapaibackend/snapAI-backend/api/views.py: Warning [MealViewSet]: Failed to obtain model through view's queryset due to raised exception. Prevent this either by setting "queryset = Model.objects.none()" on the view, checking for "getattr(self, "swagger_fake_view", False)" in get_queryset() or by simply using @extend_schema. (Exception: Field 'id' expected a number but got <django.contrib.auth.models.AnonymousUser object at 0x79ab31268a50>.)
2025-09-25 07:27:38,883: /home/snapaibackend/snapAI-backend/api/views.py: Warning [MealViewSet]: could not derive type of path parameter "id" because it is untyped and obtaining queryset from the viewset failed. Consider adding a type to the path (e.g. <int:id>) or annotating the parameter type with @extend_schema. Defaulting to "string".
2025-09-25 07:27:38,895: /home/snapaibackend/snapAI-backend/api/views.py: Warning [PlanViewSet]: Failed to obtain model through view's queryset due to raised exception. Prevent this either by setting "queryset = Model.objects.none()" on the view, checking for "getattr(self, "swagger_fake_view", False)" in get_queryset() or by simply using @extend_schema. (Exception: Field 'id' expected a number but got <django.contrib.auth.models.AnonymousUser object at 0x79ab31268a50>.)
2025-09-25 07:27:38,898: /home/snapaibackend/snapAI-backend/api/views.py: Warning [PlanViewSet]: could not derive type of path parameter "id" because it is untyped and obtaining queryset from the viewset failed. Consider adding a type to the path (e.g. <int:id>) or annotating the parameter type with @extend_schema. Defaulting to "string".
2025-09-25 07:27:38,901: /home/snapaibackend/snapAI-backend/api/views.py: Warning [ProfileViewSet]: could not derive type of path parameter "id" because it is untyped and obtaining queryset from the viewset failed. Consider adding a type to the path (e.g. <int:id>) or annotating the parameter type with @extend_schema. Defaulting to "string".
2025-09-25 07:27:38,914: /home/snapaibackend/snapAI-backend/api/views.py: Warning [RatingViewSet]: Failed to obtain model through view's queryset due to raised exception. Prevent this either by setting "queryset = Model.objects.none()" on the view, checking for "getattr(self, "swagger_fake_view", False)" in get_queryset() or by simply using @extend_schema. (Exception: Field 'id' expected a number but got <django.contrib.auth.models.AnonymousUser object at 0x79ab31268a50>.)
2025-09-25 07:27:38,918: /home/snapaibackend/snapAI-backend/api/views.py: Warning [RatingViewSet]: could not derive type of path parameter "id" because it is untyped and obtaining queryset from the viewset failed. Consider adding a type to the path (e.g. <int:id>) or annotating the parameter type with @extend_schema. Defaulting to "string".
2025-09-25 07:31:36,380: Not Found: /
2025-09-26 18:18:02,298: /home/snapaibackend/snapAI-backend/api/views.py: Error [AnalyzePhoto]: unable to guess serializer. This is graceful fallback handling for APIViews. Consider using GenericAPIView as view base class, if view is under your control. Either way you may want to add a serializer_class (or method). Ignoring view for now.
2025-09-26 18:18:02,308: /home/snapaibackend/snapAI-backend/api/views.py: Error [ResendOTPView]: unable to guess serializer. This is graceful fallback handling for APIViews. Consider using GenericAPIView as view base class, if view is under your control. Either way you may want to add a serializer_class (or method). Ignoring view for now.
2025-09-26 18:18:02,309: /home/snapaibackend/snapAI-backend/api/views.py: Error [StartSignupView]: unable to guess serializer. This is graceful fallback handling for APIViews. Consider using GenericAPIView as view base class, if view is under your control. Either way you may want to add a serializer_class (or method). Ignoring view for now.
2025-09-26 18:18:02,310: /home/snapaibackend/snapAI-backend/api/views.py: Error [VerifySignupView]: unable to guess serializer. This is graceful fallback handling for APIViews. Consider using GenericAPIView as view base class, if view is under your control. Either way you may want to add a serializer_class (or method). Ignoring view for now.
2025-09-26 18:18:02,316: /home/snapaibackend/snapAI-backend/api/views.py: Warning [MealViewSet]: Failed to obtain model through view's queryset due to raised exception. Prevent this either by setting "queryset = Model.objects.none()" on the view, checking for "getattr(self, "swagger_fake_view", False)" in get_queryset() or by simply using @extend_schema. (Exception: Field 'id' expected a number but got <django.contrib.auth.models.AnonymousUser object at 0x7b0a15388a50>.)
2025-09-26 18:18:02,322: /home/snapaibackend/snapAI-backend/api/views.py: Warning [MealViewSet]: could not derive type of path parameter "id" because it is untyped and obtaining queryset from the viewset failed. Consider adding a type to the path (e.g. <int:id>) or annotating the parameter type with @extend_schema. Defaulting to "string".
2025-09-26 18:18:02,328: /home/snapaibackend/snapAI-backend/api/views.py: Warning [PlanViewSet]: Failed to obtain model through view's queryset due to raised exception. Prevent this either by setting "queryset = Model.objects.none()" on the view, checking for "getattr(self, "swagger_fake_view", False)" in get_queryset() or by simply using @extend_schema. (Exception: Field 'id' expected a number but got <django.contrib.auth.models.AnonymousUser object at 0x7b0a15388a50>.)
2025-09-26 18:18:02,330: /home/snapaibackend/snapAI-backend/api/views.py: Warning [PlanViewSet]: could not derive type of path parameter "id" because it is untyped and obtaining queryset from the viewset failed. Consider adding a type to the path (e.g. <int:id>) or annotating the parameter type with @extend_schema. Defaulting to "string".
2025-09-26 18:18:02,331: /home/snapaibackend/snapAI-backend/api/views.py: Warning [ProfileViewSet]: could not derive type of path parameter "id" because it is untyped and obtaining queryset from the viewset failed. Consider adding a type to the path (e.g. <int:id>) or annotating the parameter type with @extend_schema. Defaulting to "string".
2025-09-26 18:18:02,341: /home/snapaibackend/snapAI-backend/api/views.py: Warning [RatingViewSet]: Failed to obtain model through view's queryset due to raised exception. Prevent this either by setting "queryset = Model.objects.none()" on the view, checking for "getattr(self, "swagger_fake_view", False)" in get_queryset() or by simply using @extend_schema. (Exception: Field 'id' expected a number but got <django.contrib.auth.models.AnonymousUser object at 0x7b0a15388a50>.)
2025-09-26 18:18:02,344: /home/snapaibackend/snapAI-backend/api/views.py: Warning [RatingViewSet]: could not derive type of path parameter "id" because it is untyped and obtaining queryset from the viewset failed. Consider adding a type to the path (e.g. <int:id>) or annotating the parameter type with @extend_schema. Defaulting to "string".
2025-09-26 18:30:20,134: Bad Request: /api/auth/register/start/
2025-09-26 18:33:54,478: /home/snapaibackend/snapAI-backend/api/views.py: Error [AnalyzePhoto]: unable to guess serializer. This is graceful fallback handling for APIViews. Consider using GenericAPIView as view base class, if view is under your control. Either way you may want to add a serializer_class (or method). Ignoring view for now.
2025-09-26 18:33:54,480: /home/snapaibackend/snapAI-backend/api/views.py: Error [ResendOTPView]: unable to guess serializer. This is graceful fallback handling for APIViews. Consider using GenericAPIView as view base class, if view is under your control. Either way you may want to add a serializer_class (or method). Ignoring view for now.
2025-09-26 18:33:54,481: /home/snapaibackend/snapAI-backend/api/views.py: Error [StartSignupView]: unable to guess serializer. This is graceful fallback handling for APIViews. Consider using GenericAPIView as view base class, if view is under your control. Either way you may want to add a serializer_class (or method). Ignoring view for now.
2025-09-26 18:33:54,481: /home/snapaibackend/snapAI-backend/api/views.py: Error [VerifySignupView]: unable to guess serializer. This is graceful fallback handling for APIViews. Consider using GenericAPIView as view base class, if view is under your control. Either way you may want to add a serializer_class (or method). Ignoring view for now.
2025-09-26 18:33:54,485: /home/snapaibackend/snapAI-backend/api/views.py: Warning [MealViewSet]: Failed to obtain model through view's queryset due to raised exception. Prevent this either by setting "queryset = Model.objects.none()" on the view, checking for "getattr(self, "swagger_fake_view", False)" in get_queryset() or by simply using @extend_schema. (Exception: Field 'id' expected a number but got <django.contrib.auth.models.AnonymousUser object at 0x7b0a154209d0>.)
2025-09-26 18:33:54,488: /home/snapaibackend/snapAI-backend/api/views.py: Warning [MealViewSet]: could not derive type of path parameter "id" because it is untyped and obtaining queryset from the viewset failed. Consider adding a type to the path (e.g. <int:id>) or annotating the parameter type with @extend_schema. Defaulting to "string".
2025-09-26 18:33:54,494: /home/snapaibackend/snapAI-backend/api/views.py: Warning [PlanViewSet]: Failed to obtain model through view's queryset due to raised exception. Prevent this either by setting "queryset = Model.objects.none()" on the view, checking for "getattr(self, "swagger_fake_view", False)" in get_queryset() or by simply using @extend_schema. (Exception: Field 'id' expected a number but got <django.contrib.auth.models.AnonymousUser object at 0x7b0a154209d0>.)
2025-09-26 18:33:54,496: /home/snapaibackend/snapAI-backend/api/views.py: Warning [PlanViewSet]: could not derive type of path parameter "id" because it is untyped and obtaining queryset from the viewset failed. Consider adding a type to the path (e.g. <int:id>) or annotating the parameter type with @extend_schema. Defaulting to "string".
2025-09-26 18:33:54,496: /home/snapaibackend/snapAI-backend/api/views.py: Warning [ProfileViewSet]: could not derive type of path parameter "id" because it is untyped and obtaining queryset from the viewset failed. Consider adding a type to the path (e.g. <int:id>) or annotating the parameter type with @extend_schema. Defaulting to "string".
2025-09-26 18:33:54,502: /home/snapaibackend/snapAI-backend/api/views.py: Warning [RatingViewSet]: Failed to obtain model through view's queryset due to raised exception. Prevent this either by setting "queryset = Model.objects.none()" on the view, checking for "getattr(self, "swagger_fake_view", False)" in get_queryset() or by simply using @extend_schema. (Exception: Field 'id' expected a number but got <django.contrib.auth.models.AnonymousUser object at 0x7b0a154209d0>.)
2025-09-26 18:33:54,504: /home/snapaibackend/snapAI-backend/api/views.py: Warning [RatingViewSet]: could not derive type of path parameter "id" because it is untyped and obtaining queryset from the viewset failed. Consider adding a type to the path (e.g. <int:id>) or annotating the parameter type with @extend_schema. Defaulting to "string".
2025-09-26 18:33:59,002: Bad Request: /api/auth/register/start/
2025-09-26 18:38:27,817: Unauthorized: /api/profile/onboarding/
2025-09-26 18:54:56,463: Not Found: /static/admin/css/responsive.css
2025-09-26 18:54:56,472: Not Found: /static/admin/css/dark_mode.css
2025-09-26 18:54:56,479: Not Found: /static/admin/css/base.css
2025-09-26 18:54:56,738: Not Found: /static/admin/css/login.css
2025-09-26 18:54:56,745: Not Found: /static/admin/css/nav_sidebar.css
2025-09-26 18:54:56,751: Not Found: /static/admin/js/theme.js
2025-09-26 18:54:57,005: Not Found: /static/admin/css/responsive.css
2025-09-26 18:54:57,009: Not Found: /static/admin/css/login.css
2025-09-26 18:54:57,013: Not Found: /static/admin/css/nav_sidebar.css
2025-09-26 18:54:57,018: Not Found: /static/admin/js/nav_sidebar.js
2025-09-26 18:54:57,337: Not Found: /favicon.ico
2025-09-26 18:56:56,896: Not Found: /
2025-09-26 18:56:56,900: Not Found: /
2025-09-26 18:57:01,399: Internal Server Error: /api/schema/
Traceback (most recent call last):
  File "/home/snapaibackend/snapAI-backend/venv/lib/python3.13/site-packages/django/core/handlers/exception.py", line 55, in inner
    response = get_response(request)
  File "/home/snapaibackend/snapAI-backend/venv/lib/python3.13/site-packages/django/core/handlers/base.py", line 197, in _get_response
    response = wrapped_callback(request, *callback_args, **callback_kwargs)
  File "/home/snapaibackend/snapAI-backend/venv/lib/python3.13/site-packages/django/views/decorators/csrf.py", line 65, in _view_wrapper
    return view_func(request, *args, **kwargs)
  File "/home/snapaibackend/snapAI-backend/venv/lib/python3.13/site-packages/django/views/generic/base.py", line 105, in view
    return self.dispatch(request, *args, **kwargs)
           ~~~~~~~~~~~~~^^^^^^^^^^^^^^^^^^^^^^^^^^
  File "/home/snapaibackend/snapAI-backend/venv/lib/python3.13/site-packages/rest_framework/views.py", line 515, in dispatch
    response = self.handle_exception(exc)
  File "/home/snapaibackend/snapAI-backend/venv/lib/python3.13/site-packages/rest_framework/views.py", line 475, in handle_exception
    self.raise_uncaught_exception(exc)
    ~~~~~~~~~~~~~~~~~~~~~~~~~~~~~^^^^^
  File "/home/snapaibackend/snapAI-backend/venv/lib/python3.13/site-packages/rest_framework/views.py", line 486, in raise_uncaught_exception
    raise exc
  File "/home/snapaibackend/snapAI-backend/venv/lib/python3.13/site-packages/rest_framework/views.py", line 512, in dispatch
    response = handler(request, *args, **kwargs)
  File "/home/snapaibackend/snapAI-backend/venv/lib/python3.13/site-packages/drf_spectacular/views.py", line 84, in get
    return self._get_schema_response(request)
           ~~~~~~~~~~~~~~~~~~~~~~~~~^^^^^^^^^
  File "/home/snapaibackend/snapAI-backend/venv/lib/python3.13/site-packages/drf_spectacular/views.py", line 92, in _get_schema_response
    data=generator.get_schema(request=request, public=self.serve_public),
         ~~~~~~~~~~~~~~~~~~~~^^^^^^^^^^^^^^^^^^^^^^^^^^^^^^^^^^^^^^^^^^^
  File "/home/snapaibackend/snapAI-backend/venv/lib/python3.13/site-packages/drf_spectacular/generators.py", line 285, in get_schema
    paths=self.parse(request, public),
          ~~~~~~~~~~^^^^^^^^^^^^^^^^^
  File "/home/snapaibackend/snapAI-backend/venv/lib/python3.13/site-packages/drf_spectacular/generators.py", line 250, in parse
    assert isinstance(view.schema, AutoSchema), (
           ~~~~~~~~~~^^^^^^^^^^^^^^^^^^^^^^^^^
AssertionError: Incompatible AutoSchema used on View <class 'api.views.AnalyzePhoto'>. Is DRF's DEFAULT_SCHEMA_CLASS pointing to "drf_spectacular.openapi.AutoSchema" or any other drf-spectacular compatible AutoSchema?
2025-09-26 18:57:02,442: Internal Server Error: /api/schema/
Traceback (most recent call last):
  File "/home/snapaibackend/snapAI-backend/venv/lib/python3.13/site-packages/django/core/handlers/exception.py", line 55, in inner
    response = get_response(request)
  File "/home/snapaibackend/snapAI-backend/venv/lib/python3.13/site-packages/django/core/handlers/base.py", line 197, in _get_response
    response = wrapped_callback(request, *callback_args, **callback_kwargs)
  File "/home/snapaibackend/snapAI-backend/venv/lib/python3.13/site-packages/django/views/decorators/csrf.py", line 65, in _view_wrapper
    return view_func(request, *args, **kwargs)
  File "/home/snapaibackend/snapAI-backend/venv/lib/python3.13/site-packages/django/views/generic/base.py", line 105, in view
    return self.dispatch(request, *args, **kwargs)
           ~~~~~~~~~~~~~^^^^^^^^^^^^^^^^^^^^^^^^^^
  File "/home/snapaibackend/snapAI-backend/venv/lib/python3.13/site-packages/rest_framework/views.py", line 515, in dispatch
    response = self.handle_exception(exc)
  File "/home/snapaibackend/snapAI-backend/venv/lib/python3.13/site-packages/rest_framework/views.py", line 475, in handle_exception
    self.raise_uncaught_exception(exc)
    ~~~~~~~~~~~~~~~~~~~~~~~~~~~~~^^^^^
  File "/home/snapaibackend/snapAI-backend/venv/lib/python3.13/site-packages/rest_framework/views.py", line 486, in raise_uncaught_exception
    raise exc
  File "/home/snapaibackend/snapAI-backend/venv/lib/python3.13/site-packages/rest_framework/views.py", line 512, in dispatch
    response = handler(request, *args, **kwargs)
  File "/home/snapaibackend/snapAI-backend/venv/lib/python3.13/site-packages/drf_spectacular/views.py", line 84, in get
    return self._get_schema_response(request)
           ~~~~~~~~~~~~~~~~~~~~~~~~~^^^^^^^^^
  File "/home/snapaibackend/snapAI-backend/venv/lib/python3.13/site-packages/drf_spectacular/views.py", line 92, in _get_schema_response
    data=generator.get_schema(request=request, public=self.serve_public),
         ~~~~~~~~~~~~~~~~~~~~^^^^^^^^^^^^^^^^^^^^^^^^^^^^^^^^^^^^^^^^^^^
  File "/home/snapaibackend/snapAI-backend/venv/lib/python3.13/site-packages/drf_spectacular/generators.py", line 285, in get_schema
    paths=self.parse(request, public),
          ~~~~~~~~~~^^^^^^^^^^^^^^^^^
  File "/home/snapaibackend/snapAI-backend/venv/lib/python3.13/site-packages/drf_spectacular/generators.py", line 250, in parse
    assert isinstance(view.schema, AutoSchema), (
           ~~~~~~~~~~^^^^^^^^^^^^^^^^^^^^^^^^^
AssertionError: Incompatible AutoSchema used on View <class 'api.views.AnalyzePhoto'>. Is DRF's DEFAULT_SCHEMA_CLASS pointing to "drf_spectacular.openapi.AutoSchema" or any other drf-spectacular compatible AutoSchema?
2025-09-26 18:57:04,862: Internal Server Error: /api/schema/
Traceback (most recent call last):
  File "/home/snapaibackend/snapAI-backend/venv/lib/python3.13/site-packages/django/core/handlers/exception.py", line 55, in inner
    response = get_response(request)
  File "/home/snapaibackend/snapAI-backend/venv/lib/python3.13/site-packages/django/core/handlers/base.py", line 197, in _get_response
    response = wrapped_callback(request, *callback_args, **callback_kwargs)
  File "/home/snapaibackend/snapAI-backend/venv/lib/python3.13/site-packages/django/views/decorators/csrf.py", line 65, in _view_wrapper
    return view_func(request, *args, **kwargs)
  File "/home/snapaibackend/snapAI-backend/venv/lib/python3.13/site-packages/django/views/generic/base.py", line 105, in view
    return self.dispatch(request, *args, **kwargs)
           ~~~~~~~~~~~~~^^^^^^^^^^^^^^^^^^^^^^^^^^
  File "/home/snapaibackend/snapAI-backend/venv/lib/python3.13/site-packages/rest_framework/views.py", line 515, in dispatch
    response = self.handle_exception(exc)
  File "/home/snapaibackend/snapAI-backend/venv/lib/python3.13/site-packages/rest_framework/views.py", line 475, in handle_exception
    self.raise_uncaught_exception(exc)
    ~~~~~~~~~~~~~~~~~~~~~~~~~~~~~^^^^^
  File "/home/snapaibackend/snapAI-backend/venv/lib/python3.13/site-packages/rest_framework/views.py", line 486, in raise_uncaught_exception
    raise exc
  File "/home/snapaibackend/snapAI-backend/venv/lib/python3.13/site-packages/rest_framework/views.py", line 512, in dispatch
    response = handler(request, *args, **kwargs)
  File "/home/snapaibackend/snapAI-backend/venv/lib/python3.13/site-packages/drf_spectacular/views.py", line 84, in get
    return self._get_schema_response(request)
           ~~~~~~~~~~~~~~~~~~~~~~~~~^^^^^^^^^
  File "/home/snapaibackend/snapAI-backend/venv/lib/python3.13/site-packages/drf_spectacular/views.py", line 92, in _get_schema_response
    data=generator.get_schema(request=request, public=self.serve_public),
         ~~~~~~~~~~~~~~~~~~~~^^^^^^^^^^^^^^^^^^^^^^^^^^^^^^^^^^^^^^^^^^^
  File "/home/snapaibackend/snapAI-backend/venv/lib/python3.13/site-packages/drf_spectacular/generators.py", line 285, in get_schema
    paths=self.parse(request, public),
          ~~~~~~~~~~^^^^^^^^^^^^^^^^^
  File "/home/snapaibackend/snapAI-backend/venv/lib/python3.13/site-packages/drf_spectacular/generators.py", line 250, in parse
    assert isinstance(view.schema, AutoSchema), (
           ~~~~~~~~~~^^^^^^^^^^^^^^^^^^^^^^^^^
AssertionError: Incompatible AutoSchema used on View <class 'api.views.AnalyzePhoto'>. Is DRF's DEFAULT_SCHEMA_CLASS pointing to "drf_spectacular.openapi.AutoSchema" or any other drf-spectacular compatible AutoSchema?
2025-09-26 18:57:06,156: Internal Server Error: /api/schema/
Traceback (most recent call last):
  File "/home/snapaibackend/snapAI-backend/venv/lib/python3.13/site-packages/django/core/handlers/exception.py", line 55, in inner
    response = get_response(request)
  File "/home/snapaibackend/snapAI-backend/venv/lib/python3.13/site-packages/django/core/handlers/base.py", line 197, in _get_response
    response = wrapped_callback(request, *callback_args, **callback_kwargs)
  File "/home/snapaibackend/snapAI-backend/venv/lib/python3.13/site-packages/django/views/decorators/csrf.py", line 65, in _view_wrapper
    return view_func(request, *args, **kwargs)
  File "/home/snapaibackend/snapAI-backend/venv/lib/python3.13/site-packages/django/views/generic/base.py", line 105, in view
    return self.dispatch(request, *args, **kwargs)
           ~~~~~~~~~~~~~^^^^^^^^^^^^^^^^^^^^^^^^^^
  File "/home/snapaibackend/snapAI-backend/venv/lib/python3.13/site-packages/rest_framework/views.py", line 515, in dispatch
    response = self.handle_exception(exc)
  File "/home/snapaibackend/snapAI-backend/venv/lib/python3.13/site-packages/rest_framework/views.py", line 475, in handle_exception
    self.raise_uncaught_exception(exc)
    ~~~~~~~~~~~~~~~~~~~~~~~~~~~~~^^^^^
  File "/home/snapaibackend/snapAI-backend/venv/lib/python3.13/site-packages/rest_framework/views.py", line 486, in raise_uncaught_exception
    raise exc
  File "/home/snapaibackend/snapAI-backend/venv/lib/python3.13/site-packages/rest_framework/views.py", line 512, in dispatch
    response = handler(request, *args, **kwargs)
  File "/home/snapaibackend/snapAI-backend/venv/lib/python3.13/site-packages/drf_spectacular/views.py", line 84, in get
    return self._get_schema_response(request)
           ~~~~~~~~~~~~~~~~~~~~~~~~~^^^^^^^^^
  File "/home/snapaibackend/snapAI-backend/venv/lib/python3.13/site-packages/drf_spectacular/views.py", line 92, in _get_schema_response
    data=generator.get_schema(request=request, public=self.serve_public),
         ~~~~~~~~~~~~~~~~~~~~^^^^^^^^^^^^^^^^^^^^^^^^^^^^^^^^^^^^^^^^^^^
  File "/home/snapaibackend/snapAI-backend/venv/lib/python3.13/site-packages/drf_spectacular/generators.py", line 285, in get_schema
    paths=self.parse(request, public),
          ~~~~~~~~~~^^^^^^^^^^^^^^^^^
  File "/home/snapaibackend/snapAI-backend/venv/lib/python3.13/site-packages/drf_spectacular/generators.py", line 250, in parse
    assert isinstance(view.schema, AutoSchema), (
           ~~~~~~~~~~^^^^^^^^^^^^^^^^^^^^^^^^^
AssertionError: Incompatible AutoSchema used on View <class 'api.views.AnalyzePhoto'>. Is DRF's DEFAULT_SCHEMA_CLASS pointing to "drf_spectacular.openapi.AutoSchema" or any other drf-spectacular compatible AutoSchema?
2025-09-26 19:03:56,851: Internal Server Error: /api/schema/
Traceback (most recent call last):
  File "/home/snapaibackend/snapAI-backend/venv/lib/python3.13/site-packages/django/core/handlers/exception.py", line 55, in inner
    response = get_response(request)
  File "/home/snapaibackend/snapAI-backend/venv/lib/python3.13/site-packages/django/core/handlers/base.py", line 197, in _get_response
    response = wrapped_callback(request, *callback_args, **callback_kwargs)
  File "/home/snapaibackend/snapAI-backend/venv/lib/python3.13/site-packages/django/views/decorators/csrf.py", line 65, in _view_wrapper
    return view_func(request, *args, **kwargs)
  File "/home/snapaibackend/snapAI-backend/venv/lib/python3.13/site-packages/django/views/generic/base.py", line 105, in view
    return self.dispatch(request, *args, **kwargs)
           ~~~~~~~~~~~~~^^^^^^^^^^^^^^^^^^^^^^^^^^
  File "/home/snapaibackend/snapAI-backend/venv/lib/python3.13/site-packages/rest_framework/views.py", line 515, in dispatch
    response = self.handle_exception(exc)
  File "/home/snapaibackend/snapAI-backend/venv/lib/python3.13/site-packages/rest_framework/views.py", line 475, in handle_exception
    self.raise_uncaught_exception(exc)
    ~~~~~~~~~~~~~~~~~~~~~~~~~~~~~^^^^^
  File "/home/snapaibackend/snapAI-backend/venv/lib/python3.13/site-packages/rest_framework/views.py", line 486, in raise_uncaught_exception
    raise exc
  File "/home/snapaibackend/snapAI-backend/venv/lib/python3.13/site-packages/rest_framework/views.py", line 512, in dispatch
    response = handler(request, *args, **kwargs)
  File "/home/snapaibackend/snapAI-backend/venv/lib/python3.13/site-packages/drf_spectacular/views.py", line 84, in get
    return self._get_schema_response(request)
           ~~~~~~~~~~~~~~~~~~~~~~~~~^^^^^^^^^
  File "/home/snapaibackend/snapAI-backend/venv/lib/python3.13/site-packages/drf_spectacular/views.py", line 92, in _get_schema_response
    data=generator.get_schema(request=request, public=self.serve_public),
         ~~~~~~~~~~~~~~~~~~~~^^^^^^^^^^^^^^^^^^^^^^^^^^^^^^^^^^^^^^^^^^^
  File "/home/snapaibackend/snapAI-backend/venv/lib/python3.13/site-packages/drf_spectacular/generators.py", line 285, in get_schema
    paths=self.parse(request, public),
          ~~~~~~~~~~^^^^^^^^^^^^^^^^^
  File "/home/snapaibackend/snapAI-backend/venv/lib/python3.13/site-packages/drf_spectacular/generators.py", line 250, in parse
    assert isinstance(view.schema, AutoSchema), (
           ~~~~~~~~~~^^^^^^^^^^^^^^^^^^^^^^^^^
AssertionError: Incompatible AutoSchema used on View <class 'api.views.AnalyzePhoto'>. Is DRF's DEFAULT_SCHEMA_CLASS pointing to "drf_spectacular.openapi.AutoSchema" or any other drf-spectacular compatible AutoSchema?
2025-09-26 19:03:57,995: Internal Server Error: /api/schema/
Traceback (most recent call last):
  File "/home/snapaibackend/snapAI-backend/venv/lib/python3.13/site-packages/django/core/handlers/exception.py", line 55, in inner
    response = get_response(request)
  File "/home/snapaibackend/snapAI-backend/venv/lib/python3.13/site-packages/django/core/handlers/base.py", line 197, in _get_response
    response = wrapped_callback(request, *callback_args, **callback_kwargs)
  File "/home/snapaibackend/snapAI-backend/venv/lib/python3.13/site-packages/django/views/decorators/csrf.py", line 65, in _view_wrapper
    return view_func(request, *args, **kwargs)
  File "/home/snapaibackend/snapAI-backend/venv/lib/python3.13/site-packages/django/views/generic/base.py", line 105, in view
    return self.dispatch(request, *args, **kwargs)
           ~~~~~~~~~~~~~^^^^^^^^^^^^^^^^^^^^^^^^^^
  File "/home/snapaibackend/snapAI-backend/venv/lib/python3.13/site-packages/rest_framework/views.py", line 515, in dispatch
    response = self.handle_exception(exc)
  File "/home/snapaibackend/snapAI-backend/venv/lib/python3.13/site-packages/rest_framework/views.py", line 475, in handle_exception
    self.raise_uncaught_exception(exc)
    ~~~~~~~~~~~~~~~~~~~~~~~~~~~~~^^^^^
  File "/home/snapaibackend/snapAI-backend/venv/lib/python3.13/site-packages/rest_framework/views.py", line 486, in raise_uncaught_exception
    raise exc
  File "/home/snapaibackend/snapAI-backend/venv/lib/python3.13/site-packages/rest_framework/views.py", line 512, in dispatch
    response = handler(request, *args, **kwargs)
  File "/home/snapaibackend/snapAI-backend/venv/lib/python3.13/site-packages/drf_spectacular/views.py", line 84, in get
    return self._get_schema_response(request)
           ~~~~~~~~~~~~~~~~~~~~~~~~~^^^^^^^^^
  File "/home/snapaibackend/snapAI-backend/venv/lib/python3.13/site-packages/drf_spectacular/views.py", line 92, in _get_schema_response
    data=generator.get_schema(request=request, public=self.serve_public),
         ~~~~~~~~~~~~~~~~~~~~^^^^^^^^^^^^^^^^^^^^^^^^^^^^^^^^^^^^^^^^^^^
  File "/home/snapaibackend/snapAI-backend/venv/lib/python3.13/site-packages/drf_spectacular/generators.py", line 285, in get_schema
    paths=self.parse(request, public),
          ~~~~~~~~~~^^^^^^^^^^^^^^^^^
  File "/home/snapaibackend/snapAI-backend/venv/lib/python3.13/site-packages/drf_spectacular/generators.py", line 250, in parse
    assert isinstance(view.schema, AutoSchema), (
           ~~~~~~~~~~^^^^^^^^^^^^^^^^^^^^^^^^^
AssertionError: Incompatible AutoSchema used on View <class 'api.views.AnalyzePhoto'>. Is DRF's DEFAULT_SCHEMA_CLASS pointing to "drf_spectacular.openapi.AutoSchema" or any other drf-spectacular compatible AutoSchema?
2025-09-27 01:45:54,416: /home/snapaibackend/snapAI-backend/api/views.py: Error [AnalyzePhoto]: unable to guess serializer. This is graceful fallback handling for APIViews. Consider using GenericAPIView as view base class, if view is under your control. Either way you may want to add a serializer_class (or method). Ignoring view for now.
2025-09-27 01:45:54,449: /home/snapaibackend/snapAI-backend/api/views.py: Error [ResendOTPView]: unable to guess serializer. This is graceful fallback handling for APIViews. Consider using GenericAPIView as view base class, if view is under your control. Either way you may want to add a serializer_class (or method). Ignoring view for now.
2025-09-27 01:45:54,450: /home/snapaibackend/snapAI-backend/api/views.py: Error [StartSignupView]: unable to guess serializer. This is graceful fallback handling for APIViews. Consider using GenericAPIView as view base class, if view is under your control. Either way you may want to add a serializer_class (or method). Ignoring view for now.
2025-09-27 01:45:54,451: /home/snapaibackend/snapAI-backend/api/views.py: Error [VerifySignupView]: unable to guess serializer. This is graceful fallback handling for APIViews. Consider using GenericAPIView as view base class, if view is under your control. Either way you may want to add a serializer_class (or method). Ignoring view for now.
2025-09-27 01:45:54,534: /home/snapaibackend/snapAI-backend/api/views.py: Warning [RatingViewSet]: could not derive type of path parameter "id" because it is untyped and obtaining queryset from the viewset failed. Consider adding a type to the path (e.g. <int:id>) or annotating the parameter type with @extend_schema. Defaulting to "string".
2025-09-27 01:45:54,506: /home/snapaibackend/snapAI-backend/api/views.py: Warning [MealViewSet]: could not derive type of path parameter "id" because it is untyped and obtaining queryset from the viewset failed. Consider adding a type to the path (e.g. <int:id>) or annotating the parameter type with @extend_schema. Defaulting to "string".
2025-09-27 01:45:54,514: /home/snapaibackend/snapAI-backend/api/views.py: Warning [PlanViewSet]: could not derive type of path parameter "id" because it is untyped and obtaining queryset from the viewset failed. Consider adding a type to the path (e.g. <int:id>) or annotating the parameter type with @extend_schema. Defaulting to "string".
2025-09-27 01:45:54,515: /home/snapaibackend/snapAI-backend/api/views.py: Warning [ProfileViewSet]: could not derive type of path parameter "id" because it is untyped and obtaining queryset from the viewset failed. Consider adding a type to the path (e.g. <int:id>) or annotating the parameter type with @extend_schema. Defaulting to "string".
2025-09-27 01:46:08,143: Bad Request: /api/auth/register/start/
2025-09-27 02:16:43,049: Bad Request: /api/auth/register/resend/
2025-09-27 02:17:08,902: Bad Request: /api/auth/register/verify/
2025-09-27 03:55:21,325: Bad Gateway: /api/auth/register/resend/
2025-09-27 03:55:36,045: Bad Gateway: /api/auth/register/resend/
2025-09-27 04:04:16,255: Bad Request: /api/auth/register/start/
2025-09-27 04:07:54,544: Bad Gateway: /api/auth/register/resend/
2025-09-27 07:43:00,035: Method Not Allowed: /api/auth/register/start/
2025-09-27 07:43:01,319: Not Found: /favicon.ico
2025-09-27 07:49:46,039: Not Found: /
2025-09-27 13:53:53,998: Not Found: /
2025-09-27 13:53:59,865: Method Not Allowed: /api/auth/register/start/
2025-09-27 13:59:43,740: Not Found: /
2025-09-27 13:59:51,093: Method Not Allowed: /api/auth/register/start/
2025-09-27 14:01:43,674: Method Not Allowed: /api/auth/register/resend/
2025-09-27 14:01:52,128: Bad Request: /api/auth/register/resend/
2025-09-27 14:02:01,599: Bad Request: /api/auth/register/resend/
2025-09-27 14:02:05,581: Bad Request: /api/auth/register/resend/
2025-09-27 14:02:29,282: Bad Gateway: /api/auth/register/resend/
2025-09-27 14:05:17,894: Not Found: /
2025-09-27 14:14:21,737: Bad Request: /api/auth/register/verify/
2025-09-27 14:14:22,715: Bad Request: /api/auth/register/verify/
2025-09-27 14:14:22,718: Bad Request: /api/auth/register/verify/
2025-09-27 14:14:22,722: Bad Request: /api/auth/register/verify/
2025-09-27 14:14:22,732: Bad Request: /api/auth/register/verify/
2025-09-27 14:14:22,734: Bad Request: /api/auth/register/verify/
2025-09-27 14:27:22,478: Bad Request: /api/auth/register/resend/
2025-09-27 14:44:55,071: Error running WSGI application
2025-09-27 14:44:55,095: ModuleNotFoundError: No module named 'google'
2025-09-27 14:44:55,095:   File "/home/snapaibackend/snapAI-backend/venv/lib/python3.13/site-packages/django/core/handlers/wsgi.py", line 124, in __call__
2025-09-27 14:44:55,095:     response = self.get_response(request)
2025-09-27 14:44:55,095: 
2025-09-27 14:44:55,096:   File "/home/snapaibackend/snapAI-backend/venv/lib/python3.13/site-packages/django/core/handlers/base.py", line 140, in get_response
2025-09-27 14:44:55,096:     response = self._middleware_chain(request)
2025-09-27 14:44:55,096: 
2025-09-27 14:44:55,096:   File "/home/snapaibackend/snapAI-backend/venv/lib/python3.13/site-packages/django/core/handlers/exception.py", line 57, in inner
2025-09-27 14:44:55,096:     response = response_for_exception(request, exc)
2025-09-27 14:44:55,096: 
2025-09-27 14:44:55,096:   File "/home/snapaibackend/snapAI-backend/venv/lib/python3.13/site-packages/django/core/handlers/exception.py", line 141, in response_for_exception
2025-09-27 14:44:55,096:     response = handle_uncaught_exception(
2025-09-27 14:44:55,096:         request, get_resolver(get_urlconf()), sys.exc_info()
2025-09-27 14:44:55,096:     )
2025-09-27 14:44:55,096: 
2025-09-27 14:44:55,096:   File "/home/snapaibackend/snapAI-backend/venv/lib/python3.13/site-packages/django/core/handlers/exception.py", line 182, in handle_uncaught_exception
2025-09-27 14:44:55,097:     return debug.technical_500_response(request, *exc_info)
2025-09-27 14:44:55,097:            ~~~~~~~~~~~~~~~~~~~~~~~~~~~~^^^^^^^^^^^^^^^^^^^^
2025-09-27 14:44:55,097: 
2025-09-27 14:44:55,097:   File "/home/snapaibackend/snapAI-backend/venv/lib/python3.13/site-packages/django/views/debug.py", line 69, in technical_500_response
2025-09-27 14:44:55,097:     html = reporter.get_traceback_html()
2025-09-27 14:44:55,097: 
2025-09-27 14:44:55,097:   File "/home/snapaibackend/snapAI-backend/venv/lib/python3.13/site-packages/django/views/debug.py", line 428, in get_traceback_html
2025-09-27 14:44:55,097:     c = Context(self.get_traceback_data(), use_l10n=False)
2025-09-27 14:44:55,097:                 ~~~~~~~~~~~~~~~~~~~~~~~^^
2025-09-27 14:44:55,097: 
2025-09-27 14:44:55,097:   File "/home/snapaibackend/snapAI-backend/venv/lib/python3.13/site-packages/django/views/debug.py", line 411, in get_traceback_data
2025-09-27 14:44:55,098:     c["raising_view_name"] = get_caller(self.request)
2025-09-27 14:44:55,098:                              ~~~~~~~~~~^^^^^^^^^^^^^^
2025-09-27 14:44:55,098: 
2025-09-27 14:44:55,098:   File "/home/snapaibackend/snapAI-backend/venv/lib/python3.13/site-packages/django/views/debug.py", line 102, in get_caller
2025-09-27 14:44:55,098:     resolver_match = resolve(request.path)
2025-09-27 14:44:55,098: 
2025-09-27 14:44:55,098:   File "/home/snapaibackend/snapAI-backend/venv/lib/python3.13/site-packages/django/urls/base.py", line 25, in resolve
2025-09-27 14:44:55,098:     return get_resolver(urlconf).resolve(path)
2025-09-27 14:44:55,098:            ~~~~~~~~~~~~~~~~~~~~~~~~~~~~~^^^^^^
2025-09-27 14:44:55,098: 
2025-09-27 14:44:55,099:   File "/home/snapaibackend/snapAI-backend/venv/lib/python3.13/site-packages/django/urls/resolvers.py", line 666, in resolve
2025-09-27 14:44:55,099:     for pattern in self.url_patterns:
2025-09-27 14:44:55,099:                    ^^^^^^^^^^^^^^^^^
2025-09-27 14:44:55,099: 
2025-09-27 14:44:55,099:   File "/home/snapaibackend/snapAI-backend/venv/lib/python3.13/site-packages/django/utils/functional.py", line 47, in __get__
2025-09-27 14:44:55,099:     res = instance.__dict__[self.name] = self.func(instance)
2025-09-27 14:44:55,099:                                          ~~~~~~~~~^^^^^^^^^^
2025-09-27 14:44:55,099: 
2025-09-27 14:44:55,099:   File "/home/snapaibackend/snapAI-backend/venv/lib/python3.13/site-packages/django/urls/resolvers.py", line 718, in url_patterns
2025-09-27 14:44:55,100:     patterns = getattr(self.urlconf_module, "urlpatterns", self.urlconf_module)
2025-09-27 14:44:55,100:                        ^^^^^^^^^^^^^^^^^^^
2025-09-27 14:44:55,100: 
2025-09-27 14:44:55,100:   File "/home/snapaibackend/snapAI-backend/venv/lib/python3.13/site-packages/django/utils/functional.py", line 47, in __get__
2025-09-27 14:44:55,100:     res = instance.__dict__[self.name] = self.func(instance)
2025-09-27 14:44:55,100:                                          ~~~~~~~~~^^^^^^^^^^
2025-09-27 14:44:55,100: 
2025-09-27 14:44:55,100:   File "/home/snapaibackend/snapAI-backend/venv/lib/python3.13/site-packages/django/urls/resolvers.py", line 711, in urlconf_module
2025-09-27 14:44:55,100:     return import_module(self.urlconf_name)
2025-09-27 14:44:55,101: 
2025-09-27 14:44:55,101:   File "/home/snapaibackend/snapAI-backend/snapAI/urls.py", line 5, in <module>
2025-09-27 14:44:55,101:     path("api/", include("api.urls")),  # твои API-роуты
2025-09-27 14:44:55,101:                  ~~~~~~~^^^^^^^^^^^^
2025-09-27 14:44:55,101: 
2025-09-27 14:44:55,101:   File "/home/snapaibackend/snapAI-backend/venv/lib/python3.13/site-packages/django/urls/conf.py", line 39, in include
2025-09-27 14:44:55,101:     urlconf_module = import_module(urlconf_module)
2025-09-27 14:44:55,101: 
2025-09-27 14:44:55,101:   File "/home/snapaibackend/snapAI-backend/api/urls.py", line 6, in <module>
2025-09-27 14:44:55,102:     from .views_auth_social import GoogleLoginView, AppleLoginView
2025-09-27 14:44:55,102: 
2025-09-27 14:44:55,102:   File "/home/snapaibackend/snapAI-backend/api/views_auth_social.py", line 12, in <module>
2025-09-27 14:44:55,102:     from .services.social_verify import verify_google_id_token, verify_apple_id_token
2025-09-27 14:44:55,102: 
2025-09-27 14:44:55,102:   File "/home/snapaibackend/snapAI-backend/api/services/social_verify.py", line 2, in <module>
2025-09-27 14:44:55,102:     from google.oauth2 import id_token as google_id_token
2025-09-27 14:46:28,498:   File "/home/snapaibackend/snapAI-backend/venv/lib/python3.13/site-packages/django/views/debug.py", line 69, in technical_500_response
2025-09-27 14:46:28,498:     html = reporter.get_traceback_html()
2025-09-27 14:46:28,499: 
2025-09-27 14:46:28,499:   File "/home/snapaibackend/snapAI-backend/venv/lib/python3.13/site-packages/django/views/debug.py", line 428, in get_traceback_html
2025-09-27 14:46:28,499:     c = Context(self.get_traceback_data(), use_l10n=False)
2025-09-27 14:46:28,499:                 ~~~~~~~~~~~~~~~~~~~~~~~^^
2025-09-27 14:46:28,499: 
2025-09-27 14:46:28,499:   File "/home/snapaibackend/snapAI-backend/venv/lib/python3.13/site-packages/django/views/debug.py", line 411, in get_traceback_data
2025-09-27 14:46:28,499:     c["raising_view_name"] = get_caller(self.request)
2025-09-27 14:46:28,499:                              ~~~~~~~~~~^^^^^^^^^^^^^^
2025-09-27 14:46:28,499: 
2025-09-27 14:46:28,499:   File "/home/snapaibackend/snapAI-backend/venv/lib/python3.13/site-packages/django/views/debug.py", line 102, in get_caller
2025-09-27 14:46:28,499:     resolver_match = resolve(request.path)
2025-09-27 14:46:28,500: 
2025-09-27 14:46:28,500:   File "/home/snapaibackend/snapAI-backend/venv/lib/python3.13/site-packages/django/urls/base.py", line 25, in resolve
2025-09-27 14:46:28,500:     return get_resolver(urlconf).resolve(path)
2025-09-27 14:46:28,500:            ~~~~~~~~~~~~~~~~~~~~~~~~~~~~~^^^^^^
2025-09-27 14:46:28,500: 
2025-09-27 14:46:28,500:   File "/home/snapaibackend/snapAI-backend/venv/lib/python3.13/site-packages/django/urls/resolvers.py", line 666, in resolve
2025-09-27 14:46:28,500:     for pattern in self.url_patterns:
2025-09-27 14:46:28,500:                    ^^^^^^^^^^^^^^^^^
2025-09-27 14:46:28,500: 
2025-09-27 14:46:28,500:   File "/home/snapaibackend/snapAI-backend/venv/lib/python3.13/site-packages/django/utils/functional.py", line 47, in __get__
2025-09-27 14:46:28,500:     res = instance.__dict__[self.name] = self.func(instance)
2025-09-27 14:46:28,500:                                          ~~~~~~~~~^^^^^^^^^^
2025-09-27 14:46:28,501: 
2025-09-27 14:46:28,501:   File "/home/snapaibackend/snapAI-backend/venv/lib/python3.13/site-packages/django/urls/resolvers.py", line 718, in url_patterns
2025-09-27 14:46:28,501:     patterns = getattr(self.urlconf_module, "urlpatterns", self.urlconf_module)
2025-09-27 14:46:28,501:                        ^^^^^^^^^^^^^^^^^^^
2025-09-27 14:46:28,501: 
2025-09-27 14:46:28,501:   File "/home/snapaibackend/snapAI-backend/venv/lib/python3.13/site-packages/django/utils/functional.py", line 47, in __get__
2025-09-27 14:46:28,501:     res = instance.__dict__[self.name] = self.func(instance)
2025-09-27 14:46:28,501:                                          ~~~~~~~~~^^^^^^^^^^
2025-09-27 14:46:28,501: 
2025-09-27 14:46:28,501:   File "/home/snapaibackend/snapAI-backend/venv/lib/python3.13/site-packages/django/urls/resolvers.py", line 711, in urlconf_module
2025-09-27 14:46:28,501:     return import_module(self.urlconf_name)
2025-09-27 14:46:28,501: 
2025-09-27 14:46:28,502:   File "/home/snapaibackend/snapAI-backend/snapAI/urls.py", line 5, in <module>
2025-09-27 14:46:28,502:     path("api/", include("api.urls")),  # твои API-роуты
2025-09-27 14:46:28,502:                  ~~~~~~~^^^^^^^^^^^^
2025-09-27 14:46:28,502: 
2025-09-27 14:46:28,502:   File "/home/snapaibackend/snapAI-backend/venv/lib/python3.13/site-packages/django/urls/conf.py", line 39, in include
2025-09-27 14:46:28,502:     urlconf_module = import_module(urlconf_module)
2025-09-27 14:46:28,502: 
2025-09-27 14:46:28,502:   File "/home/snapaibackend/snapAI-backend/api/urls.py", line 6, in <module>
2025-09-27 14:46:28,502:     from .views_auth_social import GoogleLoginView, AppleLoginView
2025-09-27 14:46:28,502: 
2025-09-27 14:46:28,502:   File "/home/snapaibackend/snapAI-backend/api/views_auth_social.py", line 12, in <module>
2025-09-27 14:46:28,502:     from .services.social_verify import verify_google_id_token, verify_apple_id_token
2025-09-27 14:46:28,503: 
2025-09-27 14:46:28,503:   File "/home/snapaibackend/snapAI-backend/api/services/social_verify.py", line 2, in <module>
2025-09-27 14:46:28,503:     from google.oauth2 import id_token as google_id_token
2025-09-27 14:46:28,485: Error running WSGI application
2025-09-27 14:46:28,497: ModuleNotFoundError: No module named 'google'
2025-09-27 14:46:28,497:   File "/home/snapaibackend/snapAI-backend/venv/lib/python3.13/site-packages/django/core/handlers/wsgi.py", line 124, in __call__
2025-09-27 14:46:28,497:     response = self.get_response(request)
2025-09-27 14:46:28,497: 
2025-09-27 14:46:28,497:   File "/home/snapaibackend/snapAI-backend/venv/lib/python3.13/site-packages/django/core/handlers/base.py", line 140, in get_response
2025-09-27 14:46:28,497:     response = self._middleware_chain(request)
2025-09-27 14:46:28,497: 
2025-09-27 14:46:28,497:   File "/home/snapaibackend/snapAI-backend/venv/lib/python3.13/site-packages/django/core/handlers/exception.py", line 57, in inner
2025-09-27 14:46:28,497:     response = response_for_exception(request, exc)
2025-09-27 14:46:28,498: 
2025-09-27 14:46:28,498:   File "/home/snapaibackend/snapAI-backend/venv/lib/python3.13/site-packages/django/core/handlers/exception.py", line 141, in response_for_exception
2025-09-27 14:46:28,498:     response = handle_uncaught_exception(
2025-09-27 14:46:28,498:         request, get_resolver(get_urlconf()), sys.exc_info()
2025-09-27 14:46:28,498:     )
2025-09-27 14:46:28,498: 
2025-09-27 14:46:28,498:   File "/home/snapaibackend/snapAI-backend/venv/lib/python3.13/site-packages/django/core/handlers/exception.py", line 182, in handle_uncaught_exception
2025-09-27 14:46:28,498:     return debug.technical_500_response(request, *exc_info)
2025-09-27 14:46:28,498:            ~~~~~~~~~~~~~~~~~~~~~~~~~~~~^^^^^^^^^^^^^^^^^^^^
2025-09-27 14:46:28,498: 
2025-09-27 14:46:52,604: Error running WSGI application
2025-09-27 14:46:52,622: ModuleNotFoundError: No module named 'google'
2025-09-27 14:46:52,622:   File "/home/snapaibackend/snapAI-backend/venv/lib/python3.13/site-packages/django/core/handlers/wsgi.py", line 124, in __call__
2025-09-27 14:46:52,623:     response = self.get_response(request)
2025-09-27 14:46:52,623: 
2025-09-27 14:46:52,623:   File "/home/snapaibackend/snapAI-backend/venv/lib/python3.13/site-packages/django/core/handlers/base.py", line 140, in get_response
2025-09-27 14:46:52,623:     response = self._middleware_chain(request)
2025-09-27 14:46:52,623: 
2025-09-27 14:46:52,623:   File "/home/snapaibackend/snapAI-backend/venv/lib/python3.13/site-packages/django/core/handlers/exception.py", line 57, in inner
2025-09-27 14:46:52,623:     response = response_for_exception(request, exc)
2025-09-27 14:46:52,624: 
2025-09-27 14:46:52,624:   File "/home/snapaibackend/snapAI-backend/venv/lib/python3.13/site-packages/django/core/handlers/exception.py", line 141, in response_for_exception
2025-09-27 14:46:52,624:     response = handle_uncaught_exception(
2025-09-27 14:46:52,624:         request, get_resolver(get_urlconf()), sys.exc_info()
2025-09-27 14:46:52,624:     )
2025-09-27 14:46:52,624: 
2025-09-27 14:46:52,624:   File "/home/snapaibackend/snapAI-backend/venv/lib/python3.13/site-packages/django/core/handlers/exception.py", line 182, in handle_uncaught_exception
2025-09-27 14:46:52,624:     return debug.technical_500_response(request, *exc_info)
2025-09-27 14:46:52,625:            ~~~~~~~~~~~~~~~~~~~~~~~~~~~~^^^^^^^^^^^^^^^^^^^^
2025-09-27 14:46:52,625: 
2025-09-27 14:46:52,625:   File "/home/snapaibackend/snapAI-backend/venv/lib/python3.13/site-packages/django/views/debug.py", line 69, in technical_500_response
2025-09-27 14:46:52,625:     html = reporter.get_traceback_html()
2025-09-27 14:46:52,625: 
2025-09-27 14:46:52,625:   File "/home/snapaibackend/snapAI-backend/venv/lib/python3.13/site-packages/django/views/debug.py", line 428, in get_traceback_html
2025-09-27 14:46:52,625:     c = Context(self.get_traceback_data(), use_l10n=False)
2025-09-27 14:46:52,626:                 ~~~~~~~~~~~~~~~~~~~~~~~^^
2025-09-27 14:46:52,626: 
2025-09-27 14:46:52,626:   File "/home/snapaibackend/snapAI-backend/venv/lib/python3.13/site-packages/django/views/debug.py", line 411, in get_traceback_data
2025-09-27 14:46:52,626:     c["raising_view_name"] = get_caller(self.request)
2025-09-27 14:46:52,626:                              ~~~~~~~~~~^^^^^^^^^^^^^^
2025-09-27 14:46:52,626: 
2025-09-27 14:46:52,626:   File "/home/snapaibackend/snapAI-backend/venv/lib/python3.13/site-packages/django/views/debug.py", line 102, in get_caller
2025-09-27 14:46:52,627:     resolver_match = resolve(request.path)
2025-09-27 14:46:52,627: 
2025-09-27 14:46:52,627:   File "/home/snapaibackend/snapAI-backend/venv/lib/python3.13/site-packages/django/urls/base.py", line 25, in resolve
2025-09-27 14:46:52,627:     return get_resolver(urlconf).resolve(path)
2025-09-27 14:46:52,627:            ~~~~~~~~~~~~~~~~~~~~~~~~~~~~~^^^^^^
2025-09-27 14:46:52,627: 
2025-09-27 14:46:52,627:   File "/home/snapaibackend/snapAI-backend/venv/lib/python3.13/site-packages/django/urls/resolvers.py", line 666, in resolve
2025-09-27 14:46:52,627:     for pattern in self.url_patterns:
2025-09-27 14:46:52,628:                    ^^^^^^^^^^^^^^^^^
2025-09-27 14:46:52,628: 
2025-09-27 14:46:52,628:   File "/home/snapaibackend/snapAI-backend/venv/lib/python3.13/site-packages/django/utils/functional.py", line 47, in __get__
2025-09-27 14:46:52,628:     res = instance.__dict__[self.name] = self.func(instance)
2025-09-27 14:46:52,628:                                          ~~~~~~~~~^^^^^^^^^^
2025-09-27 14:46:52,628: 
2025-09-27 14:46:52,628:   File "/home/snapaibackend/snapAI-backend/venv/lib/python3.13/site-packages/django/urls/resolvers.py", line 718, in url_patterns
2025-09-27 14:46:52,629:     patterns = getattr(self.urlconf_module, "urlpatterns", self.urlconf_module)
2025-09-27 14:46:52,629:                        ^^^^^^^^^^^^^^^^^^^
2025-09-27 14:46:52,629: 
2025-09-27 14:46:52,629:   File "/home/snapaibackend/snapAI-backend/venv/lib/python3.13/site-packages/django/utils/functional.py", line 47, in __get__
2025-09-27 14:46:52,629:     res = instance.__dict__[self.name] = self.func(instance)
2025-09-27 14:46:52,629:                                          ~~~~~~~~~^^^^^^^^^^
2025-09-27 14:46:52,629: 
2025-09-27 14:46:52,629:   File "/home/snapaibackend/snapAI-backend/venv/lib/python3.13/site-packages/django/urls/resolvers.py", line 711, in urlconf_module
2025-09-27 14:46:52,629:     return import_module(self.urlconf_name)
2025-09-27 14:46:52,629: 
2025-09-27 14:46:52,630:   File "/home/snapaibackend/snapAI-backend/snapAI/urls.py", line 5, in <module>
2025-09-27 14:46:52,630:     path("api/", include("api.urls")),  # твои API-роуты
2025-09-27 14:46:52,630:                  ~~~~~~~^^^^^^^^^^^^
2025-09-27 14:46:52,630: 
2025-09-27 14:46:52,630:   File "/home/snapaibackend/snapAI-backend/venv/lib/python3.13/site-packages/django/urls/conf.py", line 39, in include
2025-09-27 14:46:52,630:     urlconf_module = import_module(urlconf_module)
2025-09-27 14:46:52,630: 
2025-09-27 14:46:52,630:   File "/home/snapaibackend/snapAI-backend/api/urls.py", line 6, in <module>
2025-09-27 14:46:52,631:     from .views_auth_social import GoogleLoginView, AppleLoginView
2025-09-27 14:46:52,631: 
2025-09-27 14:46:52,631:   File "/home/snapaibackend/snapAI-backend/api/views_auth_social.py", line 12, in <module>
2025-09-27 14:46:52,631:     from .services.social_verify import verify_google_id_token, verify_apple_id_token
2025-09-27 14:46:52,631: 
2025-09-27 14:46:52,631:   File "/home/snapaibackend/snapAI-backend/api/services/social_verify.py", line 2, in <module>
2025-09-27 14:46:52,632:     from google.oauth2 import id_token as google_id_token
2025-09-27 14:47:17,472: Error running WSGI application
2025-09-27 14:47:17,483: ModuleNotFoundError: No module named 'google'
2025-09-27 14:47:17,483:   File "/home/snapaibackend/snapAI-backend/venv/lib/python3.13/site-packages/django/core/handlers/wsgi.py", line 124, in __call__
2025-09-27 14:47:17,483:     response = self.get_response(request)
2025-09-27 14:47:17,483: 
2025-09-27 14:47:17,483:   File "/home/snapaibackend/snapAI-backend/venv/lib/python3.13/site-packages/django/core/handlers/base.py", line 140, in get_response
2025-09-27 14:47:17,484:     response = self._middleware_chain(request)
2025-09-27 14:47:17,484: 
2025-09-27 14:47:17,484:   File "/home/snapaibackend/snapAI-backend/venv/lib/python3.13/site-packages/django/core/handlers/exception.py", line 57, in inner
2025-09-27 14:47:17,484:     response = response_for_exception(request, exc)
2025-09-27 14:47:17,484: 
2025-09-27 14:47:17,484:   File "/home/snapaibackend/snapAI-backend/venv/lib/python3.13/site-packages/django/core/handlers/exception.py", line 141, in response_for_exception
2025-09-27 14:47:17,485:     response = handle_uncaught_exception(
2025-09-27 14:47:17,485:         request, get_resolver(get_urlconf()), sys.exc_info()
2025-09-27 14:47:17,485:     )
2025-09-27 14:47:17,485: 
2025-09-27 14:47:17,485:   File "/home/snapaibackend/snapAI-backend/venv/lib/python3.13/site-packages/django/core/handlers/exception.py", line 182, in handle_uncaught_exception
2025-09-27 14:47:17,485:     return debug.technical_500_response(request, *exc_info)
2025-09-27 14:47:17,485:            ~~~~~~~~~~~~~~~~~~~~~~~~~~~~^^^^^^^^^^^^^^^^^^^^
2025-09-27 14:47:17,485: 
2025-09-27 14:47:17,485:   File "/home/snapaibackend/snapAI-backend/venv/lib/python3.13/site-packages/django/views/debug.py", line 69, in technical_500_response
2025-09-27 14:47:17,486:     html = reporter.get_traceback_html()
2025-09-27 14:47:17,486: 
2025-09-27 14:47:17,486:   File "/home/snapaibackend/snapAI-backend/venv/lib/python3.13/site-packages/django/views/debug.py", line 428, in get_traceback_html
2025-09-27 14:47:17,486:     c = Context(self.get_traceback_data(), use_l10n=False)
2025-09-27 14:47:17,486:                 ~~~~~~~~~~~~~~~~~~~~~~~^^
2025-09-27 14:47:17,486: 
2025-09-27 14:47:17,486:   File "/home/snapaibackend/snapAI-backend/venv/lib/python3.13/site-packages/django/views/debug.py", line 411, in get_traceback_data
2025-09-27 14:47:17,486:     c["raising_view_name"] = get_caller(self.request)
2025-09-27 14:47:17,486:                              ~~~~~~~~~~^^^^^^^^^^^^^^
2025-09-27 14:47:17,486: 
2025-09-27 14:47:17,486:   File "/home/snapaibackend/snapAI-backend/venv/lib/python3.13/site-packages/django/views/debug.py", line 102, in get_caller
2025-09-27 14:47:17,487:     resolver_match = resolve(request.path)
2025-09-27 14:47:17,487: 
2025-09-27 14:47:17,487:   File "/home/snapaibackend/snapAI-backend/venv/lib/python3.13/site-packages/django/urls/base.py", line 25, in resolve
2025-09-27 14:47:17,487:     return get_resolver(urlconf).resolve(path)
2025-09-27 14:47:17,487:            ~~~~~~~~~~~~~~~~~~~~~~~~~~~~~^^^^^^
2025-09-27 14:47:17,487: 
2025-09-27 14:47:17,487:   File "/home/snapaibackend/snapAI-backend/venv/lib/python3.13/site-packages/django/urls/resolvers.py", line 666, in resolve
2025-09-27 14:47:17,487:     for pattern in self.url_patterns:
2025-09-27 14:47:17,487:                    ^^^^^^^^^^^^^^^^^
2025-09-27 14:47:17,487: 
2025-09-27 14:47:17,487:   File "/home/snapaibackend/snapAI-backend/venv/lib/python3.13/site-packages/django/utils/functional.py", line 47, in __get__
2025-09-27 14:47:17,487:     res = instance.__dict__[self.name] = self.func(instance)
2025-09-27 14:47:17,488:                                          ~~~~~~~~~^^^^^^^^^^
2025-09-27 14:47:17,488: 
2025-09-27 14:47:17,488:   File "/home/snapaibackend/snapAI-backend/venv/lib/python3.13/site-packages/django/urls/resolvers.py", line 718, in url_patterns
2025-09-27 14:47:17,488:     patterns = getattr(self.urlconf_module, "urlpatterns", self.urlconf_module)
2025-09-27 14:47:17,488:                        ^^^^^^^^^^^^^^^^^^^
2025-09-27 14:47:17,488: 
2025-09-27 14:47:17,488:   File "/home/snapaibackend/snapAI-backend/venv/lib/python3.13/site-packages/django/utils/functional.py", line 47, in __get__
2025-09-27 14:47:17,488:     res = instance.__dict__[self.name] = self.func(instance)
2025-09-27 14:47:17,488:                                          ~~~~~~~~~^^^^^^^^^^
2025-09-27 14:47:17,488: 
2025-09-27 14:47:17,488:   File "/home/snapaibackend/snapAI-backend/venv/lib/python3.13/site-packages/django/urls/resolvers.py", line 711, in urlconf_module
2025-09-27 14:47:17,488:     return import_module(self.urlconf_name)
2025-09-27 14:47:17,489: 
2025-09-27 14:47:17,489:   File "/home/snapaibackend/snapAI-backend/snapAI/urls.py", line 5, in <module>
2025-09-27 14:47:17,489:     path("api/", include("api.urls")),  # твои API-роуты
2025-09-27 14:47:17,489:                  ~~~~~~~^^^^^^^^^^^^
2025-09-27 14:47:17,489: 
2025-09-27 14:47:17,489:   File "/home/snapaibackend/snapAI-backend/venv/lib/python3.13/site-packages/django/urls/conf.py", line 39, in include
2025-09-27 14:47:17,489:     urlconf_module = import_module(urlconf_module)
2025-09-27 14:47:17,489: 
2025-09-27 14:47:17,489:   File "/home/snapaibackend/snapAI-backend/api/urls.py", line 6, in <module>
2025-09-27 14:47:17,489:     from .views_auth_social import GoogleLoginView, AppleLoginView
2025-09-27 14:47:17,489: 
2025-09-27 14:47:17,490:   File "/home/snapaibackend/snapAI-backend/api/views_auth_social.py", line 12, in <module>
2025-09-27 14:47:17,490:     from .services.social_verify import verify_google_id_token, verify_apple_id_token
2025-09-27 14:47:17,490: 
2025-09-27 14:47:17,490:   File "/home/snapaibackend/snapAI-backend/api/services/social_verify.py", line 2, in <module>
2025-09-27 14:47:17,490:     from google.oauth2 import id_token as google_id_token
2025-09-27 14:47:23,148: Error running WSGI application
2025-09-27 14:47:23,160: ModuleNotFoundError: No module named 'google'
2025-09-27 14:47:23,160:   File "/home/snapaibackend/snapAI-backend/venv/lib/python3.13/site-packages/django/core/handlers/wsgi.py", line 124, in __call__
2025-09-27 14:47:23,160:     response = self.get_response(request)
2025-09-27 14:47:23,161: 
2025-09-27 14:47:23,161:   File "/home/snapaibackend/snapAI-backend/venv/lib/python3.13/site-packages/django/core/handlers/base.py", line 140, in get_response
2025-09-27 14:47:23,161:     response = self._middleware_chain(request)
2025-09-27 14:47:23,161: 
2025-09-27 14:47:23,161:   File "/home/snapaibackend/snapAI-backend/venv/lib/python3.13/site-packages/django/core/handlers/exception.py", line 57, in inner
2025-09-27 14:47:23,161:     response = response_for_exception(request, exc)
2025-09-27 14:47:23,161: 
2025-09-27 14:47:23,161:   File "/home/snapaibackend/snapAI-backend/venv/lib/python3.13/site-packages/django/core/handlers/exception.py", line 141, in response_for_exception
2025-09-27 14:47:23,161:     response = handle_uncaught_exception(
2025-09-27 14:47:23,162:         request, get_resolver(get_urlconf()), sys.exc_info()
2025-09-27 14:47:23,162:     )
2025-09-27 14:47:23,162: 
2025-09-27 14:47:23,162:   File "/home/snapaibackend/snapAI-backend/venv/lib/python3.13/site-packages/django/core/handlers/exception.py", line 182, in handle_uncaught_exception
2025-09-27 14:47:23,162:     return debug.technical_500_response(request, *exc_info)
2025-09-27 14:47:23,162:            ~~~~~~~~~~~~~~~~~~~~~~~~~~~~^^^^^^^^^^^^^^^^^^^^
2025-09-27 14:47:23,162: 
2025-09-27 14:47:23,162:   File "/home/snapaibackend/snapAI-backend/venv/lib/python3.13/site-packages/django/views/debug.py", line 69, in technical_500_response
2025-09-27 14:47:23,163:     html = reporter.get_traceback_html()
2025-09-27 14:47:23,163: 
2025-09-27 14:47:23,163:   File "/home/snapaibackend/snapAI-backend/venv/lib/python3.13/site-packages/django/views/debug.py", line 428, in get_traceback_html
2025-09-27 14:47:23,163:     c = Context(self.get_traceback_data(), use_l10n=False)
2025-09-27 14:47:23,163:                 ~~~~~~~~~~~~~~~~~~~~~~~^^
2025-09-27 14:47:23,163: 
2025-09-27 14:47:23,163:   File "/home/snapaibackend/snapAI-backend/venv/lib/python3.13/site-packages/django/views/debug.py", line 411, in get_traceback_data
2025-09-27 14:47:23,163:     c["raising_view_name"] = get_caller(self.request)
2025-09-27 14:47:23,163:                              ~~~~~~~~~~^^^^^^^^^^^^^^
2025-09-27 14:47:23,164: 
2025-09-27 14:47:23,164:   File "/home/snapaibackend/snapAI-backend/venv/lib/python3.13/site-packages/django/views/debug.py", line 102, in get_caller
2025-09-27 14:47:23,164:     resolver_match = resolve(request.path)
2025-09-27 14:47:23,164: 
2025-09-27 14:47:23,164:   File "/home/snapaibackend/snapAI-backend/venv/lib/python3.13/site-packages/django/urls/base.py", line 25, in resolve
2025-09-27 14:47:23,164:     return get_resolver(urlconf).resolve(path)
2025-09-27 14:47:23,164:            ~~~~~~~~~~~~~~~~~~~~~~~~~~~~~^^^^^^
2025-09-27 14:47:23,164: 
2025-09-27 14:47:23,165:   File "/home/snapaibackend/snapAI-backend/venv/lib/python3.13/site-packages/django/urls/resolvers.py", line 666, in resolve
2025-09-27 14:47:23,165:     for pattern in self.url_patterns:
2025-09-27 14:47:23,165:                    ^^^^^^^^^^^^^^^^^
2025-09-27 14:47:23,165: 
2025-09-27 14:47:23,165:   File "/home/snapaibackend/snapAI-backend/venv/lib/python3.13/site-packages/django/utils/functional.py", line 47, in __get__
2025-09-27 14:47:23,165:     res = instance.__dict__[self.name] = self.func(instance)
2025-09-27 14:47:23,165:                                          ~~~~~~~~~^^^^^^^^^^
2025-09-27 14:47:23,165: 
2025-09-27 14:47:23,165:   File "/home/snapaibackend/snapAI-backend/venv/lib/python3.13/site-packages/django/urls/resolvers.py", line 718, in url_patterns
2025-09-27 14:47:23,166:     patterns = getattr(self.urlconf_module, "urlpatterns", self.urlconf_module)
2025-09-27 14:47:23,166:                        ^^^^^^^^^^^^^^^^^^^
2025-09-27 14:47:23,166: 
2025-09-27 14:47:23,166:   File "/home/snapaibackend/snapAI-backend/venv/lib/python3.13/site-packages/django/utils/functional.py", line 47, in __get__
2025-09-27 14:47:23,166:     res = instance.__dict__[self.name] = self.func(instance)
2025-09-27 14:47:23,166:                                          ~~~~~~~~~^^^^^^^^^^
2025-09-27 14:47:23,166: 
2025-09-27 14:47:23,166:   File "/home/snapaibackend/snapAI-backend/venv/lib/python3.13/site-packages/django/urls/resolvers.py", line 711, in urlconf_module
2025-09-27 14:47:23,166:     return import_module(self.urlconf_name)
2025-09-27 14:47:23,167: 
2025-09-27 14:47:23,167:   File "/home/snapaibackend/snapAI-backend/snapAI/urls.py", line 5, in <module>
2025-09-27 14:47:23,167:     path("api/", include("api.urls")),  # твои API-роуты
2025-09-27 14:47:23,167:                  ~~~~~~~^^^^^^^^^^^^
2025-09-27 14:47:23,167: 
2025-09-27 14:47:23,167:   File "/home/snapaibackend/snapAI-backend/venv/lib/python3.13/site-packages/django/urls/conf.py", line 39, in include
2025-09-27 14:47:23,167:     urlconf_module = import_module(urlconf_module)
2025-09-27 14:47:23,167: 
2025-09-27 14:47:23,168:   File "/home/snapaibackend/snapAI-backend/api/urls.py", line 6, in <module>
2025-09-27 14:47:23,168:     from .views_auth_social import GoogleLoginView, AppleLoginView
2025-09-27 14:47:23,168: 
2025-09-27 14:47:23,168:   File "/home/snapaibackend/snapAI-backend/api/views_auth_social.py", line 12, in <module>
2025-09-27 14:47:23,168:     from .services.social_verify import verify_google_id_token, verify_apple_id_token
2025-09-27 14:47:23,168: 
2025-09-27 14:47:23,168:   File "/home/snapaibackend/snapAI-backend/api/services/social_verify.py", line 2, in <module>
2025-09-27 14:47:23,168:     from google.oauth2 import id_token as google_id_token
2025-09-27 14:48:08,333: Error running WSGI application
2025-09-27 14:48:08,345: ModuleNotFoundError: No module named 'google'
2025-09-27 14:48:08,345:   File "/home/snapaibackend/snapAI-backend/venv/lib/python3.13/site-packages/django/core/handlers/wsgi.py", line 124, in __call__
2025-09-27 14:48:08,345:     response = self.get_response(request)
2025-09-27 14:48:08,345: 
2025-09-27 14:48:08,345:   File "/home/snapaibackend/snapAI-backend/venv/lib/python3.13/site-packages/django/core/handlers/base.py", line 140, in get_response
2025-09-27 14:48:08,346:     response = self._middleware_chain(request)
2025-09-27 14:48:08,346: 
2025-09-27 14:48:08,346:   File "/home/snapaibackend/snapAI-backend/venv/lib/python3.13/site-packages/django/core/handlers/exception.py", line 57, in inner
2025-09-27 14:48:08,346:     response = response_for_exception(request, exc)
2025-09-27 14:48:08,346: 
2025-09-27 14:48:08,346:   File "/home/snapaibackend/snapAI-backend/venv/lib/python3.13/site-packages/django/core/handlers/exception.py", line 141, in response_for_exception
2025-09-27 14:48:08,346:     response = handle_uncaught_exception(
2025-09-27 14:48:08,346:         request, get_resolver(get_urlconf()), sys.exc_info()
2025-09-27 14:48:08,346:     )
2025-09-27 14:48:08,346: 
2025-09-27 14:48:08,346:   File "/home/snapaibackend/snapAI-backend/venv/lib/python3.13/site-packages/django/core/handlers/exception.py", line 182, in handle_uncaught_exception
2025-09-27 14:48:08,346:     return debug.technical_500_response(request, *exc_info)
2025-09-27 14:48:08,347:            ~~~~~~~~~~~~~~~~~~~~~~~~~~~~^^^^^^^^^^^^^^^^^^^^
2025-09-27 14:48:08,347: 
2025-09-27 14:48:08,347:   File "/home/snapaibackend/snapAI-backend/venv/lib/python3.13/site-packages/django/views/debug.py", line 69, in technical_500_response
2025-09-27 14:48:08,347:     html = reporter.get_traceback_html()
2025-09-27 14:48:08,347: 
2025-09-27 14:48:08,347:   File "/home/snapaibackend/snapAI-backend/venv/lib/python3.13/site-packages/django/views/debug.py", line 428, in get_traceback_html
2025-09-27 14:48:08,347:     c = Context(self.get_traceback_data(), use_l10n=False)
2025-09-27 14:48:08,347:                 ~~~~~~~~~~~~~~~~~~~~~~~^^
2025-09-27 14:48:08,347: 
2025-09-27 14:48:08,347:   File "/home/snapaibackend/snapAI-backend/venv/lib/python3.13/site-packages/django/views/debug.py", line 411, in get_traceback_data
2025-09-27 14:48:08,348:     c["raising_view_name"] = get_caller(self.request)
2025-09-27 14:48:08,348:                              ~~~~~~~~~~^^^^^^^^^^^^^^
2025-09-27 14:48:08,348: 
2025-09-27 14:48:08,348:   File "/home/snapaibackend/snapAI-backend/venv/lib/python3.13/site-packages/django/views/debug.py", line 102, in get_caller
2025-09-27 14:48:08,348:     resolver_match = resolve(request.path)
2025-09-27 14:48:08,348: 
2025-09-27 14:48:08,348:   File "/home/snapaibackend/snapAI-backend/venv/lib/python3.13/site-packages/django/urls/base.py", line 25, in resolve
2025-09-27 14:48:08,348:     return get_resolver(urlconf).resolve(path)
2025-09-27 14:48:08,348:            ~~~~~~~~~~~~~~~~~~~~~~~~~~~~~^^^^^^
2025-09-27 14:48:08,348: 
2025-09-27 14:48:08,349:   File "/home/snapaibackend/snapAI-backend/venv/lib/python3.13/site-packages/django/urls/resolvers.py", line 666, in resolve
2025-09-27 14:48:08,349:     for pattern in self.url_patterns:
2025-09-27 14:48:08,349:                    ^^^^^^^^^^^^^^^^^
2025-09-27 14:48:08,349: 
2025-09-27 14:48:08,349:   File "/home/snapaibackend/snapAI-backend/venv/lib/python3.13/site-packages/django/utils/functional.py", line 47, in __get__
2025-09-27 14:48:08,349:     res = instance.__dict__[self.name] = self.func(instance)
2025-09-27 14:48:08,349:                                          ~~~~~~~~~^^^^^^^^^^
2025-09-27 14:48:08,349: 
2025-09-27 14:48:08,349:   File "/home/snapaibackend/snapAI-backend/venv/lib/python3.13/site-packages/django/urls/resolvers.py", line 718, in url_patterns
2025-09-27 14:48:08,350:     patterns = getattr(self.urlconf_module, "urlpatterns", self.urlconf_module)
2025-09-27 14:48:08,350:                        ^^^^^^^^^^^^^^^^^^^
2025-09-27 14:48:08,350: 
2025-09-27 14:48:08,350:   File "/home/snapaibackend/snapAI-backend/venv/lib/python3.13/site-packages/django/utils/functional.py", line 47, in __get__
2025-09-27 14:48:08,350:     res = instance.__dict__[self.name] = self.func(instance)
2025-09-27 14:48:08,350:                                          ~~~~~~~~~^^^^^^^^^^
2025-09-27 14:48:08,350: 
2025-09-27 14:48:08,350:   File "/home/snapaibackend/snapAI-backend/venv/lib/python3.13/site-packages/django/urls/resolvers.py", line 711, in urlconf_module
2025-09-27 14:48:08,350:     return import_module(self.urlconf_name)
2025-09-27 14:48:08,350: 
2025-09-27 14:48:08,350:   File "/home/snapaibackend/snapAI-backend/snapAI/urls.py", line 5, in <module>
2025-09-27 14:48:08,351:     path("api/", include("api.urls")),  # твои API-роуты
2025-09-27 14:48:08,351:                  ~~~~~~~^^^^^^^^^^^^
2025-09-27 14:48:08,351: 
2025-09-27 14:48:08,351:   File "/home/snapaibackend/snapAI-backend/venv/lib/python3.13/site-packages/django/urls/conf.py", line 39, in include
2025-09-27 14:48:08,351:     urlconf_module = import_module(urlconf_module)
2025-09-27 14:48:08,351: 
2025-09-27 14:48:08,351:   File "/home/snapaibackend/snapAI-backend/api/urls.py", line 6, in <module>
2025-09-27 14:48:08,351:     from .views_auth_social import GoogleLoginView, AppleLoginView
2025-09-27 14:48:08,351: 
2025-09-27 14:48:08,352:   File "/home/snapaibackend/snapAI-backend/api/views_auth_social.py", line 12, in <module>
2025-09-27 14:48:08,352:     from .services.social_verify import verify_google_id_token, verify_apple_id_token
2025-09-27 14:48:08,352: 
2025-09-27 14:48:08,352:   File "/home/snapaibackend/snapAI-backend/api/services/social_verify.py", line 2, in <module>
2025-09-27 14:48:08,352:     from google.oauth2 import id_token as google_id_token
2025-09-27 14:48:15,178: ModuleNotFoundError: No module named 'google'
2025-09-27 14:48:15,178:   File "/home/snapaibackend/snapAI-backend/venv/lib/python3.13/site-packages/django/core/handlers/wsgi.py", line 124, in __call__
2025-09-27 14:48:15,179:     response = self.get_response(request)
2025-09-27 14:48:15,179: 
2025-09-27 14:48:15,179:   File "/home/snapaibackend/snapAI-backend/venv/lib/python3.13/site-packages/django/core/handlers/base.py", line 140, in get_response
2025-09-27 14:48:15,179:     response = self._middleware_chain(request)
2025-09-27 14:48:15,182: 
2025-09-27 14:48:15,182:   File "/home/snapaibackend/snapAI-backend/venv/lib/python3.13/site-packages/django/core/handlers/exception.py", line 57, in inner
2025-09-27 14:48:15,182:     response = response_for_exception(request, exc)
2025-09-27 14:48:15,182: 
2025-09-27 14:48:15,182:   File "/home/snapaibackend/snapAI-backend/venv/lib/python3.13/site-packages/django/core/handlers/exception.py", line 141, in response_for_exception
2025-09-27 14:48:15,183:     response = handle_uncaught_exception(
2025-09-27 14:48:15,183:         request, get_resolver(get_urlconf()), sys.exc_info()
2025-09-27 14:48:15,183:     )
2025-09-27 14:48:15,183: 
2025-09-27 14:48:15,183:   File "/home/snapaibackend/snapAI-backend/venv/lib/python3.13/site-packages/django/core/handlers/exception.py", line 182, in handle_uncaught_exception
2025-09-27 14:48:15,183:     return debug.technical_500_response(request, *exc_info)
2025-09-27 14:48:15,184:            ~~~~~~~~~~~~~~~~~~~~~~~~~~~~^^^^^^^^^^^^^^^^^^^^
2025-09-27 14:48:15,184: 
2025-09-27 14:48:15,184:   File "/home/snapaibackend/snapAI-backend/venv/lib/python3.13/site-packages/django/views/debug.py", line 69, in technical_500_response
2025-09-27 14:48:15,184:     html = reporter.get_traceback_html()
2025-09-27 14:48:15,184: 
2025-09-27 14:48:15,184:   File "/home/snapaibackend/snapAI-backend/venv/lib/python3.13/site-packages/django/views/debug.py", line 428, in get_traceback_html
2025-09-27 14:48:15,185:     c = Context(self.get_traceback_data(), use_l10n=False)
2025-09-27 14:48:15,185:                 ~~~~~~~~~~~~~~~~~~~~~~~^^
2025-09-27 14:48:15,185: 
2025-09-27 14:48:15,185:   File "/home/snapaibackend/snapAI-backend/venv/lib/python3.13/site-packages/django/views/debug.py", line 411, in get_traceback_data
2025-09-27 14:48:15,185:     c["raising_view_name"] = get_caller(self.request)
2025-09-27 14:48:15,186:                              ~~~~~~~~~~^^^^^^^^^^^^^^
2025-09-27 14:48:15,186: 
2025-09-27 14:48:15,186:   File "/home/snapaibackend/snapAI-backend/venv/lib/python3.13/site-packages/django/views/debug.py", line 102, in get_caller
2025-09-27 14:48:15,186:     resolver_match = resolve(request.path)
2025-09-27 14:48:15,186: 
2025-09-27 14:48:15,186:   File "/home/snapaibackend/snapAI-backend/venv/lib/python3.13/site-packages/django/urls/base.py", line 25, in resolve
2025-09-27 14:48:15,187:     return get_resolver(urlconf).resolve(path)
2025-09-27 14:48:15,187:            ~~~~~~~~~~~~~~~~~~~~~~~~~~~~~^^^^^^
2025-09-27 14:48:15,188: 
2025-09-27 14:48:15,189:   File "/home/snapaibackend/snapAI-backend/venv/lib/python3.13/site-packages/django/urls/resolvers.py", line 666, in resolve
2025-09-27 14:48:15,189:     for pattern in self.url_patterns:
2025-09-27 14:48:15,189:                    ^^^^^^^^^^^^^^^^^
2025-09-27 14:48:15,190: 
2025-09-27 14:48:15,190:   File "/home/snapaibackend/snapAI-backend/venv/lib/python3.13/site-packages/django/utils/functional.py", line 47, in __get__
2025-09-27 14:48:15,190:     res = instance.__dict__[self.name] = self.func(instance)
2025-09-27 14:48:15,191:                                          ~~~~~~~~~^^^^^^^^^^
2025-09-27 14:48:15,191: 
2025-09-27 14:48:15,193:   File "/home/snapaibackend/snapAI-backend/venv/lib/python3.13/site-packages/django/urls/resolvers.py", line 718, in url_patterns
2025-09-27 14:48:15,193:     patterns = getattr(self.urlconf_module, "urlpatterns", self.urlconf_module)
2025-09-27 14:48:15,194:                        ^^^^^^^^^^^^^^^^^^^
2025-09-27 14:48:15,194: 
2025-09-27 14:48:15,194:   File "/home/snapaibackend/snapAI-backend/venv/lib/python3.13/site-packages/django/utils/functional.py", line 47, in __get__
2025-09-27 14:48:15,195:     res = instance.__dict__[self.name] = self.func(instance)
2025-09-27 14:48:15,195:                                          ~~~~~~~~~^^^^^^^^^^
2025-09-27 14:48:15,195: 
2025-09-27 14:48:15,196:   File "/home/snapaibackend/snapAI-backend/venv/lib/python3.13/site-packages/django/urls/resolvers.py", line 711, in urlconf_module
2025-09-27 14:48:15,196:     return import_module(self.urlconf_name)
2025-09-27 14:48:15,196: 
2025-09-27 14:48:15,196:   File "/home/snapaibackend/snapAI-backend/snapAI/urls.py", line 5, in <module>
2025-09-27 14:48:15,196:     path("api/", include("api.urls")),  # твои API-роуты
2025-09-27 14:48:15,196:                  ~~~~~~~^^^^^^^^^^^^
2025-09-27 14:48:15,197: 
2025-09-27 14:48:15,197:   File "/home/snapaibackend/snapAI-backend/venv/lib/python3.13/site-packages/django/urls/conf.py", line 39, in include
2025-09-27 14:48:15,197:     urlconf_module = import_module(urlconf_module)
2025-09-27 14:48:15,197: 
2025-09-27 14:48:15,197:   File "/home/snapaibackend/snapAI-backend/api/urls.py", line 6, in <module>
2025-09-27 14:48:15,198:     from .views_auth_social import GoogleLoginView, AppleLoginView
2025-09-27 14:48:15,198: 
2025-09-27 14:48:15,198:   File "/home/snapaibackend/snapAI-backend/api/views_auth_social.py", line 12, in <module>
2025-09-27 14:48:15,198:     from .services.social_verify import verify_google_id_token, verify_apple_id_token
2025-09-27 14:48:15,199: 
2025-09-27 14:48:15,199:   File "/home/snapaibackend/snapAI-backend/api/services/social_verify.py", line 2, in <module>
2025-09-27 14:48:15,199:     from google.oauth2 import id_token as google_id_token
2025-09-27 14:48:15,141: Error running WSGI application
2025-09-27 14:48:22,308: Error running WSGI application
2025-09-27 14:48:22,334: ModuleNotFoundError: No module named 'google'
2025-09-27 14:48:22,334:   File "/home/snapaibackend/snapAI-backend/venv/lib/python3.13/site-packages/django/core/handlers/wsgi.py", line 124, in __call__
2025-09-27 14:48:22,334:     response = self.get_response(request)
2025-09-27 14:48:22,334: 
2025-09-27 14:48:22,335:   File "/home/snapaibackend/snapAI-backend/venv/lib/python3.13/site-packages/django/core/handlers/base.py", line 140, in get_response
2025-09-27 14:48:22,335:     response = self._middleware_chain(request)
2025-09-27 14:48:22,335: 
2025-09-27 14:48:22,335:   File "/home/snapaibackend/snapAI-backend/venv/lib/python3.13/site-packages/django/core/handlers/exception.py", line 57, in inner
2025-09-27 14:48:22,335:     response = response_for_exception(request, exc)
2025-09-27 14:48:22,335: 
2025-09-27 14:48:22,335:   File "/home/snapaibackend/snapAI-backend/venv/lib/python3.13/site-packages/django/core/handlers/exception.py", line 141, in response_for_exception
2025-09-27 14:48:22,336:     response = handle_uncaught_exception(
2025-09-27 14:48:22,336:         request, get_resolver(get_urlconf()), sys.exc_info()
2025-09-27 14:48:22,336:     )
2025-09-27 14:48:22,336: 
2025-09-27 14:48:22,336:   File "/home/snapaibackend/snapAI-backend/venv/lib/python3.13/site-packages/django/core/handlers/exception.py", line 182, in handle_uncaught_exception
2025-09-27 14:48:22,337:     return debug.technical_500_response(request, *exc_info)
2025-09-27 14:48:22,337:            ~~~~~~~~~~~~~~~~~~~~~~~~~~~~^^^^^^^^^^^^^^^^^^^^
2025-09-27 14:48:22,337: 
2025-09-27 14:48:22,337:   File "/home/snapaibackend/snapAI-backend/venv/lib/python3.13/site-packages/django/views/debug.py", line 69, in technical_500_response
2025-09-27 14:48:22,337:     html = reporter.get_traceback_html()
2025-09-27 14:48:22,337: 
2025-09-27 14:48:22,338:   File "/home/snapaibackend/snapAI-backend/venv/lib/python3.13/site-packages/django/views/debug.py", line 428, in get_traceback_html
2025-09-27 14:48:28,809: ModuleNotFoundError: No module named 'google'
2025-09-27 14:48:28,810:   File "/home/snapaibackend/snapAI-backend/venv/lib/python3.13/site-packages/django/core/handlers/wsgi.py", line 124, in __call__
2025-09-27 14:48:28,810:     response = self.get_response(request)
2025-09-27 14:48:28,810: 
2025-09-27 14:48:28,810:   File "/home/snapaibackend/snapAI-backend/venv/lib/python3.13/site-packages/django/core/handlers/base.py", line 140, in get_response
2025-09-27 14:48:28,810:     response = self._middleware_chain(request)
2025-09-27 14:48:28,810: 
2025-09-27 14:48:28,810:   File "/home/snapaibackend/snapAI-backend/venv/lib/python3.13/site-packages/django/core/handlers/exception.py", line 57, in inner
2025-09-27 14:48:28,810:     response = response_for_exception(request, exc)
2025-09-27 14:48:28,810: 
2025-09-27 14:48:28,810:   File "/home/snapaibackend/snapAI-backend/venv/lib/python3.13/site-packages/django/core/handlers/exception.py", line 141, in response_for_exception
2025-09-27 14:48:28,811:     response = handle_uncaught_exception(
2025-09-27 14:48:28,811:         request, get_resolver(get_urlconf()), sys.exc_info()
2025-09-27 14:48:28,811:     )
2025-09-27 14:48:28,811: 
2025-09-27 14:48:28,811:   File "/home/snapaibackend/snapAI-backend/venv/lib/python3.13/site-packages/django/core/handlers/exception.py", line 182, in handle_uncaught_exception
2025-09-27 14:48:28,811:     return debug.technical_500_response(request, *exc_info)
2025-09-27 14:48:28,811:            ~~~~~~~~~~~~~~~~~~~~~~~~~~~~^^^^^^^^^^^^^^^^^^^^
2025-09-27 14:48:28,811: 
2025-09-27 14:48:28,811:   File "/home/snapaibackend/snapAI-backend/venv/lib/python3.13/site-packages/django/views/debug.py", line 69, in technical_500_response
2025-09-27 14:48:28,811:     html = reporter.get_traceback_html()
2025-09-27 14:48:28,811: 
2025-09-27 14:48:28,812:   File "/home/snapaibackend/snapAI-backend/venv/lib/python3.13/site-packages/django/views/debug.py", line 428, in get_traceback_html
2025-09-27 14:48:28,812:     c = Context(self.get_traceback_data(), use_l10n=False)
2025-09-27 14:48:28,812:                 ~~~~~~~~~~~~~~~~~~~~~~~^^
2025-09-27 14:48:28,812: 
2025-09-27 14:48:28,812:   File "/home/snapaibackend/snapAI-backend/venv/lib/python3.13/site-packages/django/views/debug.py", line 411, in get_traceback_data
2025-09-27 14:48:28,812:     c["raising_view_name"] = get_caller(self.request)
2025-09-27 14:48:28,812:                              ~~~~~~~~~~^^^^^^^^^^^^^^
2025-09-27 14:48:28,812: 
2025-09-27 14:48:28,812:   File "/home/snapaibackend/snapAI-backend/venv/lib/python3.13/site-packages/django/views/debug.py", line 102, in get_caller
2025-09-27 14:48:28,812:     resolver_match = resolve(request.path)
2025-09-27 14:48:28,812: 
2025-09-27 14:48:28,813:   File "/home/snapaibackend/snapAI-backend/venv/lib/python3.13/site-packages/django/urls/base.py", line 25, in resolve
2025-09-27 14:48:28,813:     return get_resolver(urlconf).resolve(path)
2025-09-27 14:48:28,813:            ~~~~~~~~~~~~~~~~~~~~~~~~~~~~~^^^^^^
2025-09-27 14:48:28,813: 
2025-09-27 14:48:28,813:   File "/home/snapaibackend/snapAI-backend/venv/lib/python3.13/site-packages/django/urls/resolvers.py", line 666, in resolve
2025-09-27 14:48:28,813:     for pattern in self.url_patterns:
2025-09-27 14:48:28,813:                    ^^^^^^^^^^^^^^^^^
2025-09-27 14:48:28,813: 
2025-09-27 14:48:28,813:   File "/home/snapaibackend/snapAI-backend/venv/lib/python3.13/site-packages/django/utils/functional.py", line 47, in __get__
2025-09-27 14:48:28,813:     res = instance.__dict__[self.name] = self.func(instance)
2025-09-27 14:48:28,813:                                          ~~~~~~~~~^^^^^^^^^^
2025-09-27 14:48:28,814: 
2025-09-27 14:48:28,814:   File "/home/snapaibackend/snapAI-backend/venv/lib/python3.13/site-packages/django/urls/resolvers.py", line 718, in url_patterns
2025-09-27 14:48:28,814:     patterns = getattr(self.urlconf_module, "urlpatterns", self.urlconf_module)
2025-09-27 14:48:28,814:                        ^^^^^^^^^^^^^^^^^^^
2025-09-27 14:48:28,814: 
2025-09-27 14:48:28,814:   File "/home/snapaibackend/snapAI-backend/venv/lib/python3.13/site-packages/django/utils/functional.py", line 47, in __get__
2025-09-27 14:48:28,814:     res = instance.__dict__[self.name] = self.func(instance)
2025-09-27 14:48:28,814:                                          ~~~~~~~~~^^^^^^^^^^
2025-09-27 14:48:28,814: 
2025-09-27 14:48:28,814:   File "/home/snapaibackend/snapAI-backend/venv/lib/python3.13/site-packages/django/urls/resolvers.py", line 711, in urlconf_module
2025-09-27 14:48:28,815:     return import_module(self.urlconf_name)
2025-09-27 14:48:28,815: 
2025-09-27 14:48:28,815:   File "/home/snapaibackend/snapAI-backend/snapAI/urls.py", line 5, in <module>
2025-09-27 14:48:28,815:     path("api/", include("api.urls")),  # твои API-роуты
2025-09-27 14:48:28,815:                  ~~~~~~~^^^^^^^^^^^^
2025-09-27 14:48:28,815: 
2025-09-27 14:48:28,815:   File "/home/snapaibackend/snapAI-backend/venv/lib/python3.13/site-packages/django/urls/conf.py", line 39, in include
2025-09-27 14:48:28,815:     urlconf_module = import_module(urlconf_module)
2025-09-27 14:48:28,815: 
2025-09-27 14:48:28,815:   File "/home/snapaibackend/snapAI-backend/api/urls.py", line 6, in <module>
2025-09-27 14:48:28,815:     from .views_auth_social import GoogleLoginView, AppleLoginView
2025-09-27 14:48:28,816: 
2025-09-27 14:48:28,816:   File "/home/snapaibackend/snapAI-backend/api/views_auth_social.py", line 12, in <module>
2025-09-27 14:48:28,816:     from .services.social_verify import verify_google_id_token, verify_apple_id_token
2025-09-27 14:48:28,816: 
2025-09-27 14:48:28,816:   File "/home/snapaibackend/snapAI-backend/api/services/social_verify.py", line 2, in <module>
2025-09-27 14:48:28,816:     from google.oauth2 import id_token as google_id_token
2025-09-27 14:48:28,799: Error running WSGI application
2025-09-27 14:49:15,111:     c = Context(self.get_traceback_data(), use_l10n=False)
2025-09-27 14:49:15,111:                 ~~~~~~~~~~~~~~~~~~~~~~~^^
2025-09-27 14:49:15,111: 
2025-09-27 14:49:15,111:   File "/home/snapaibackend/snapAI-backend/venv/lib/python3.13/site-packages/django/views/debug.py", line 411, in get_traceback_data
2025-09-27 14:49:15,111:     c["raising_view_name"] = get_caller(self.request)
2025-09-27 14:49:15,111:                              ~~~~~~~~~~^^^^^^^^^^^^^^
2025-09-27 14:49:15,112: 
2025-09-27 14:49:15,112:   File "/home/snapaibackend/snapAI-backend/venv/lib/python3.13/site-packages/django/views/debug.py", line 102, in get_caller
2025-09-27 14:49:15,112:     resolver_match = resolve(request.path)
2025-09-27 14:49:15,113: 
2025-09-27 14:49:15,114:   File "/home/snapaibackend/snapAI-backend/venv/lib/python3.13/site-packages/django/urls/base.py", line 25, in resolve
2025-09-27 14:49:15,114:     return get_resolver(urlconf).resolve(path)
2025-09-27 14:49:15,114:            ~~~~~~~~~~~~~~~~~~~~~~~~~~~~~^^^^^^
2025-09-27 14:49:15,115: 
2025-09-27 14:49:15,115:   File "/home/snapaibackend/snapAI-backend/venv/lib/python3.13/site-packages/django/urls/resolvers.py", line 666, in resolve
2025-09-27 14:49:15,115:     for pattern in self.url_patterns:
2025-09-27 14:49:15,115:                    ^^^^^^^^^^^^^^^^^
2025-09-27 14:49:15,115: 
2025-09-27 14:49:15,116:   File "/home/snapaibackend/snapAI-backend/venv/lib/python3.13/site-packages/django/utils/functional.py", line 47, in __get__
2025-09-27 14:49:15,116:     res = instance.__dict__[self.name] = self.func(instance)
2025-09-27 14:49:15,116:                                          ~~~~~~~~~^^^^^^^^^^
2025-09-27 14:49:15,116: 
2025-09-27 14:49:15,116:   File "/home/snapaibackend/snapAI-backend/venv/lib/python3.13/site-packages/django/urls/resolvers.py", line 718, in url_patterns
2025-09-27 14:49:15,116:     patterns = getattr(self.urlconf_module, "urlpatterns", self.urlconf_module)
2025-09-27 14:49:15,117:                        ^^^^^^^^^^^^^^^^^^^
2025-09-27 14:49:15,117: 
2025-09-27 14:49:15,117:   File "/home/snapaibackend/snapAI-backend/venv/lib/python3.13/site-packages/django/utils/functional.py", line 47, in __get__
2025-09-27 14:49:15,118:     res = instance.__dict__[self.name] = self.func(instance)
2025-09-27 14:49:15,120:                                          ~~~~~~~~~^^^^^^^^^^
2025-09-27 14:49:15,120: 
2025-09-27 14:49:15,120:   File "/home/snapaibackend/snapAI-backend/venv/lib/python3.13/site-packages/django/urls/resolvers.py", line 711, in urlconf_module
2025-09-27 14:49:15,120:     return import_module(self.urlconf_name)
2025-09-27 14:49:15,120: 
2025-09-27 14:49:15,120:   File "/home/snapaibackend/snapAI-backend/snapAI/urls.py", line 5, in <module>
2025-09-27 14:49:15,121:     path("api/", include("api.urls")),  # твои API-роуты
2025-09-27 14:49:15,121:                  ~~~~~~~^^^^^^^^^^^^
2025-09-27 14:49:15,121: 
2025-09-27 14:49:15,121:   File "/home/snapaibackend/snapAI-backend/venv/lib/python3.13/site-packages/django/urls/conf.py", line 39, in include
2025-09-27 14:49:15,121:     urlconf_module = import_module(urlconf_module)
2025-09-27 14:49:15,121: 
2025-09-27 14:49:15,121:   File "/home/snapaibackend/snapAI-backend/api/urls.py", line 6, in <module>
2025-09-27 14:49:15,122:     from .views_auth_social import GoogleLoginView, AppleLoginView
2025-09-27 14:49:15,122: 
2025-09-27 14:49:15,122:   File "/home/snapaibackend/snapAI-backend/api/views_auth_social.py", line 12, in <module>
2025-09-27 14:49:15,122:     from .services.social_verify import verify_google_id_token, verify_apple_id_token
2025-09-27 14:49:15,124: 
2025-09-27 14:49:15,125:   File "/home/snapaibackend/snapAI-backend/api/services/social_verify.py", line 2, in <module>
2025-09-27 14:49:15,126:     from google.oauth2 import id_token as google_id_token
2025-09-27 14:49:15,070: Error running WSGI application
2025-09-27 14:49:15,102: ModuleNotFoundError: No module named 'google'
2025-09-27 14:49:15,104:   File "/home/snapaibackend/snapAI-backend/venv/lib/python3.13/site-packages/django/core/handlers/wsgi.py", line 124, in __call__
2025-09-27 14:49:15,104:     response = self.get_response(request)
2025-09-27 14:49:15,104: 
2025-09-27 14:49:15,105:   File "/home/snapaibackend/snapAI-backend/venv/lib/python3.13/site-packages/django/core/handlers/base.py", line 140, in get_response
2025-09-27 14:49:15,105:     response = self._middleware_chain(request)
2025-09-27 14:49:15,105: 
2025-09-27 14:49:15,105:   File "/home/snapaibackend/snapAI-backend/venv/lib/python3.13/site-packages/django/core/handlers/exception.py", line 57, in inner
2025-09-27 14:49:15,105:     response = response_for_exception(request, exc)
2025-09-27 14:49:15,106: 
2025-09-27 14:49:15,106:   File "/home/snapaibackend/snapAI-backend/venv/lib/python3.13/site-packages/django/core/handlers/exception.py", line 141, in response_for_exception
2025-09-27 14:49:15,106:     response = handle_uncaught_exception(
2025-09-27 14:49:15,106:         request, get_resolver(get_urlconf()), sys.exc_info()
2025-09-27 14:49:15,106:     )
2025-09-27 14:49:15,106: 
2025-09-27 14:49:15,106:   File "/home/snapaibackend/snapAI-backend/venv/lib/python3.13/site-packages/django/core/handlers/exception.py", line 182, in handle_uncaught_exception
2025-09-27 14:49:15,107:     return debug.technical_500_response(request, *exc_info)
2025-09-27 14:49:15,107:            ~~~~~~~~~~~~~~~~~~~~~~~~~~~~^^^^^^^^^^^^^^^^^^^^
2025-09-27 14:49:15,107: 
2025-09-27 14:49:15,109:   File "/home/snapaibackend/snapAI-backend/venv/lib/python3.13/site-packages/django/views/debug.py", line 69, in technical_500_response
2025-09-27 14:49:15,109:     html = reporter.get_traceback_html()
2025-09-27 14:49:15,109: 
2025-09-27 14:49:15,110:   File "/home/snapaibackend/snapAI-backend/venv/lib/python3.13/site-packages/django/views/debug.py", line 428, in get_traceback_html
2025-09-27 14:49:22,150: Error running WSGI application
2025-09-27 14:49:22,170: ModuleNotFoundError: No module named 'google'
2025-09-27 14:49:22,170:   File "/home/snapaibackend/snapAI-backend/venv/lib/python3.13/site-packages/django/core/handlers/wsgi.py", line 124, in __call__
2025-09-27 14:49:22,171:     response = self.get_response(request)
2025-09-27 14:49:22,171: 
2025-09-27 14:49:22,171:   File "/home/snapaibackend/snapAI-backend/venv/lib/python3.13/site-packages/django/core/handlers/base.py", line 140, in get_response
2025-09-27 14:49:22,171:     response = self._middleware_chain(request)
2025-09-27 14:49:22,171: 
2025-09-27 14:49:22,171:   File "/home/snapaibackend/snapAI-backend/venv/lib/python3.13/site-packages/django/core/handlers/exception.py", line 57, in inner
2025-09-27 14:49:22,172:     response = response_for_exception(request, exc)
2025-09-27 14:49:22,172: 
2025-09-27 14:49:22,172:   File "/home/snapaibackend/snapAI-backend/venv/lib/python3.13/site-packages/django/core/handlers/exception.py", line 141, in response_for_exception
2025-09-27 14:49:22,172:     response = handle_uncaught_exception(
2025-09-27 14:49:22,172:         request, get_resolver(get_urlconf()), sys.exc_info()
2025-09-27 14:49:22,172:     )
2025-09-27 14:49:22,173: 
2025-09-27 14:49:22,173:   File "/home/snapaibackend/snapAI-backend/venv/lib/python3.13/site-packages/django/core/handlers/exception.py", line 182, in handle_uncaught_exception
2025-09-27 14:49:22,173:     return debug.technical_500_response(request, *exc_info)
2025-09-27 14:49:22,173:            ~~~~~~~~~~~~~~~~~~~~~~~~~~~~^^^^^^^^^^^^^^^^^^^^
2025-09-27 14:49:22,173: 
2025-09-27 14:49:22,173:   File "/home/snapaibackend/snapAI-backend/venv/lib/python3.13/site-packages/django/views/debug.py", line 69, in technical_500_response
2025-09-27 14:49:22,174:     html = reporter.get_traceback_html()
2025-09-27 14:49:22,174: 
2025-09-27 14:49:22,174:   File "/home/snapaibackend/snapAI-backend/venv/lib/python3.13/site-packages/django/views/debug.py", line 428, in get_traceback_html
2025-09-27 14:49:22,174:     c = Context(self.get_traceback_data(), use_l10n=False)
2025-09-27 14:49:22,174:                 ~~~~~~~~~~~~~~~~~~~~~~~^^
2025-09-27 14:49:22,174: 
2025-09-27 14:49:22,175:   File "/home/snapaibackend/snapAI-backend/venv/lib/python3.13/site-packages/django/views/debug.py", line 411, in get_traceback_data
2025-09-27 14:49:22,175:     c["raising_view_name"] = get_caller(self.request)
2025-09-27 14:49:22,175:                              ~~~~~~~~~~^^^^^^^^^^^^^^
2025-09-27 14:49:22,175: 
2025-09-27 14:49:22,175:   File "/home/snapaibackend/snapAI-backend/venv/lib/python3.13/site-packages/django/views/debug.py", line 102, in get_caller
2025-09-27 14:49:22,175:     resolver_match = resolve(request.path)
2025-09-27 14:49:22,176: 
2025-09-27 14:49:22,176:   File "/home/snapaibackend/snapAI-backend/venv/lib/python3.13/site-packages/django/urls/base.py", line 25, in resolve
2025-09-27 14:49:22,176:     return get_resolver(urlconf).resolve(path)
2025-09-27 14:49:22,176:            ~~~~~~~~~~~~~~~~~~~~~~~~~~~~~^^^^^^
2025-09-27 14:49:22,176: 
2025-09-27 14:49:22,176:   File "/home/snapaibackend/snapAI-backend/venv/lib/python3.13/site-packages/django/urls/resolvers.py", line 666, in resolve
2025-09-27 14:49:22,177:     for pattern in self.url_patterns:
2025-09-27 14:49:22,177:                    ^^^^^^^^^^^^^^^^^
2025-09-27 14:49:22,177: 
2025-09-27 14:49:22,177:   File "/home/snapaibackend/snapAI-backend/venv/lib/python3.13/site-packages/django/utils/functional.py", line 47, in __get__
2025-09-27 14:49:22,177:     res = instance.__dict__[self.name] = self.func(instance)
2025-09-27 14:49:22,177:                                          ~~~~~~~~~^^^^^^^^^^
2025-09-27 14:49:22,178: 
2025-09-27 14:49:22,178:   File "/home/snapaibackend/snapAI-backend/venv/lib/python3.13/site-packages/django/urls/resolvers.py", line 718, in url_patterns
2025-09-27 14:49:22,178:     patterns = getattr(self.urlconf_module, "urlpatterns", self.urlconf_module)
2025-09-27 14:49:22,178:                        ^^^^^^^^^^^^^^^^^^^
2025-09-27 14:49:22,178: 
2025-09-27 14:49:22,178:   File "/home/snapaibackend/snapAI-backend/venv/lib/python3.13/site-packages/django/utils/functional.py", line 47, in __get__
2025-09-27 14:49:22,179:     res = instance.__dict__[self.name] = self.func(instance)
2025-09-27 14:49:22,179:                                          ~~~~~~~~~^^^^^^^^^^
2025-09-27 14:49:22,179: 
2025-09-27 14:49:22,179:   File "/home/snapaibackend/snapAI-backend/venv/lib/python3.13/site-packages/django/urls/resolvers.py", line 711, in urlconf_module
2025-09-27 14:49:22,179:     return import_module(self.urlconf_name)
2025-09-27 14:49:22,179: 
2025-09-27 14:49:22,180:   File "/home/snapaibackend/snapAI-backend/snapAI/urls.py", line 5, in <module>
2025-09-27 14:49:22,180:     path("api/", include("api.urls")),  # твои API-роуты
2025-09-27 14:49:22,180:                  ~~~~~~~^^^^^^^^^^^^
2025-09-27 14:49:22,180: 
2025-09-27 14:49:22,180:   File "/home/snapaibackend/snapAI-backend/venv/lib/python3.13/site-packages/django/urls/conf.py", line 39, in include
2025-09-27 14:49:22,180:     urlconf_module = import_module(urlconf_module)
2025-09-27 14:49:22,181: 
2025-09-27 14:49:22,181:   File "/home/snapaibackend/snapAI-backend/api/urls.py", line 6, in <module>
2025-09-27 14:49:22,181:     from .views_auth_social import GoogleLoginView, AppleLoginView
2025-09-27 14:49:22,181: 
2025-09-27 14:49:22,181:   File "/home/snapaibackend/snapAI-backend/api/views_auth_social.py", line 12, in <module>
2025-09-27 14:49:22,181:     from .services.social_verify import verify_google_id_token, verify_apple_id_token
2025-09-27 14:49:22,182: 
2025-09-27 14:49:22,182:   File "/home/snapaibackend/snapAI-backend/api/services/social_verify.py", line 2, in <module>
2025-09-27 14:49:22,182:     from google.oauth2 import id_token as google_id_token
2025-09-27 14:50:16,057: Error running WSGI application
2025-09-27 14:50:16,069: ModuleNotFoundError: No module named 'google'
2025-09-27 14:50:16,069:   File "/home/snapaibackend/snapAI-backend/venv/lib/python3.13/site-packages/django/core/handlers/wsgi.py", line 124, in __call__
2025-09-27 14:50:16,069:     response = self.get_response(request)
2025-09-27 14:50:16,069: 
2025-09-27 14:50:16,069:   File "/home/snapaibackend/snapAI-backend/venv/lib/python3.13/site-packages/django/core/handlers/base.py", line 140, in get_response
2025-09-27 14:50:16,069:     response = self._middleware_chain(request)
2025-09-27 14:50:16,069: 
2025-09-27 14:50:16,069:   File "/home/snapaibackend/snapAI-backend/venv/lib/python3.13/site-packages/django/core/handlers/exception.py", line 57, in inner
2025-09-27 14:50:16,070:     response = response_for_exception(request, exc)
2025-09-27 14:50:16,070: 
2025-09-27 14:50:16,070:   File "/home/snapaibackend/snapAI-backend/venv/lib/python3.13/site-packages/django/core/handlers/exception.py", line 141, in response_for_exception
2025-09-27 14:50:16,070:     response = handle_uncaught_exception(
2025-09-27 14:50:16,070:         request, get_resolver(get_urlconf()), sys.exc_info()
2025-09-27 14:50:16,070:     )
2025-09-27 14:50:16,070: 
2025-09-27 14:50:16,070:   File "/home/snapaibackend/snapAI-backend/venv/lib/python3.13/site-packages/django/core/handlers/exception.py", line 182, in handle_uncaught_exception
2025-09-27 14:50:16,070:     return debug.technical_500_response(request, *exc_info)
2025-09-27 14:50:16,070:            ~~~~~~~~~~~~~~~~~~~~~~~~~~~~^^^^^^^^^^^^^^^^^^^^
2025-09-27 14:50:16,070: 
2025-09-27 14:50:16,071:   File "/home/snapaibackend/snapAI-backend/venv/lib/python3.13/site-packages/django/views/debug.py", line 69, in technical_500_response
2025-09-27 14:50:16,071:     html = reporter.get_traceback_html()
2025-09-27 14:50:16,071: 
2025-09-27 14:50:16,071:   File "/home/snapaibackend/snapAI-backend/venv/lib/python3.13/site-packages/django/views/debug.py", line 428, in get_traceback_html
2025-09-27 14:50:16,071:     c = Context(self.get_traceback_data(), use_l10n=False)
2025-09-27 14:50:16,071:                 ~~~~~~~~~~~~~~~~~~~~~~~^^
2025-09-27 14:50:16,071: 
2025-09-27 14:50:16,071:   File "/home/snapaibackend/snapAI-backend/venv/lib/python3.13/site-packages/django/views/debug.py", line 411, in get_traceback_data
2025-09-27 14:50:16,071:     c["raising_view_name"] = get_caller(self.request)
2025-09-27 14:50:16,072:                              ~~~~~~~~~~^^^^^^^^^^^^^^
2025-09-27 14:50:16,072: 
2025-09-27 14:50:16,072:   File "/home/snapaibackend/snapAI-backend/venv/lib/python3.13/site-packages/django/views/debug.py", line 102, in get_caller
2025-09-27 14:50:16,072:     resolver_match = resolve(request.path)
2025-09-27 14:50:16,072: 
2025-09-27 14:50:16,072:   File "/home/snapaibackend/snapAI-backend/venv/lib/python3.13/site-packages/django/urls/base.py", line 25, in resolve
2025-09-27 14:50:16,072:     return get_resolver(urlconf).resolve(path)
2025-09-27 14:50:16,072:            ~~~~~~~~~~~~~~~~~~~~~~~~~~~~~^^^^^^
2025-09-27 14:50:16,073: 
2025-09-27 14:50:16,073:   File "/home/snapaibackend/snapAI-backend/venv/lib/python3.13/site-packages/django/urls/resolvers.py", line 666, in resolve
2025-09-27 14:50:16,073:     for pattern in self.url_patterns:
2025-09-27 14:50:16,073:                    ^^^^^^^^^^^^^^^^^
2025-09-27 14:50:16,073: 
2025-09-27 14:50:16,073:   File "/home/snapaibackend/snapAI-backend/venv/lib/python3.13/site-packages/django/utils/functional.py", line 47, in __get__
2025-09-27 14:50:16,073:     res = instance.__dict__[self.name] = self.func(instance)
2025-09-27 14:50:16,073:                                          ~~~~~~~~~^^^^^^^^^^
2025-09-27 14:50:16,073: 
2025-09-27 14:50:16,073:   File "/home/snapaibackend/snapAI-backend/venv/lib/python3.13/site-packages/django/urls/resolvers.py", line 718, in url_patterns
2025-09-27 14:50:16,074:     patterns = getattr(self.urlconf_module, "urlpatterns", self.urlconf_module)
2025-09-27 14:50:16,074:                        ^^^^^^^^^^^^^^^^^^^
2025-09-27 14:50:16,074: 
2025-09-27 14:50:16,074:   File "/home/snapaibackend/snapAI-backend/venv/lib/python3.13/site-packages/django/utils/functional.py", line 47, in __get__
2025-09-27 14:50:16,074:     res = instance.__dict__[self.name] = self.func(instance)
2025-09-27 14:50:16,074:                                          ~~~~~~~~~^^^^^^^^^^
2025-09-27 14:50:16,074: 
2025-09-27 14:50:16,074:   File "/home/snapaibackend/snapAI-backend/venv/lib/python3.13/site-packages/django/urls/resolvers.py", line 711, in urlconf_module
2025-09-27 14:50:16,074:     return import_module(self.urlconf_name)
2025-09-27 14:50:16,074: 
2025-09-27 14:50:16,074:   File "/home/snapaibackend/snapAI-backend/snapAI/urls.py", line 5, in <module>
2025-09-27 14:50:16,074:     path("api/", include("api.urls")),  # твои API-роуты
2025-09-27 14:50:16,075:                  ~~~~~~~^^^^^^^^^^^^
2025-09-27 14:50:16,075: 
2025-09-27 14:50:16,075:   File "/home/snapaibackend/snapAI-backend/venv/lib/python3.13/site-packages/django/urls/conf.py", line 39, in include
2025-09-27 14:50:16,075:     urlconf_module = import_module(urlconf_module)
2025-09-27 14:50:16,075: 
2025-09-27 14:50:16,075:   File "/home/snapaibackend/snapAI-backend/api/urls.py", line 6, in <module>
2025-09-27 14:50:16,075:     from .views_auth_social import GoogleLoginView, AppleLoginView
2025-09-27 14:50:16,075: 
2025-09-27 14:50:16,075:   File "/home/snapaibackend/snapAI-backend/api/views_auth_social.py", line 12, in <module>
2025-09-27 14:50:16,075:     from .services.social_verify import verify_google_id_token, verify_apple_id_token
2025-09-27 14:50:16,075: 
2025-09-27 14:50:16,076:   File "/home/snapaibackend/snapAI-backend/api/services/social_verify.py", line 2, in <module>
2025-09-27 14:50:16,076:     from google.oauth2 import id_token as google_id_token
2025-09-27 14:51:06,314: Error running WSGI application
2025-09-27 14:51:06,338: 
2025-09-27 14:51:06,338:   File "/home/snapaibackend/snapAI-backend/venv/lib/python3.13/site-packages/django/views/debug.py", line 428, in get_traceback_html
2025-09-27 14:51:06,338:     c = Context(self.get_traceback_data(), use_l10n=False)
2025-09-27 14:51:06,338:                 ~~~~~~~~~~~~~~~~~~~~~~~^^
2025-09-27 14:51:06,339: 
2025-09-27 14:51:06,339:   File "/home/snapaibackend/snapAI-backend/venv/lib/python3.13/site-packages/django/views/debug.py", line 411, in get_traceback_data
2025-09-27 14:51:06,339:     c["raising_view_name"] = get_caller(self.request)
2025-09-27 14:51:06,339:                              ~~~~~~~~~~^^^^^^^^^^^^^^
2025-09-27 14:51:06,339: 
2025-09-27 14:51:06,339:   File "/home/snapaibackend/snapAI-backend/venv/lib/python3.13/site-packages/django/views/debug.py", line 102, in get_caller
2025-09-27 14:51:06,339:     resolver_match = resolve(request.path)
2025-09-27 14:51:06,335: ModuleNotFoundError: No module named 'google'
2025-09-27 14:51:06,335:   File "/home/snapaibackend/snapAI-backend/venv/lib/python3.13/site-packages/django/core/handlers/wsgi.py", line 124, in __call__
2025-09-27 14:51:06,336:     response = self.get_response(request)
2025-09-27 14:51:06,336: 
2025-09-27 14:51:06,336:   File "/home/snapaibackend/snapAI-backend/venv/lib/python3.13/site-packages/django/core/handlers/base.py", line 140, in get_response
2025-09-27 14:51:06,336:     response = self._middleware_chain(request)
2025-09-27 14:51:06,336: 
2025-09-27 14:51:06,336:   File "/home/snapaibackend/snapAI-backend/venv/lib/python3.13/site-packages/django/core/handlers/exception.py", line 57, in inner
2025-09-27 14:51:06,336:     response = response_for_exception(request, exc)
2025-09-27 14:51:06,336: 
2025-09-27 14:51:06,337:   File "/home/snapaibackend/snapAI-backend/venv/lib/python3.13/site-packages/django/core/handlers/exception.py", line 141, in response_for_exception
2025-09-27 14:51:06,337:     response = handle_uncaught_exception(
2025-09-27 14:51:06,337:         request, get_resolver(get_urlconf()), sys.exc_info()
2025-09-27 14:51:06,339: 
2025-09-27 14:51:06,339:   File "/home/snapaibackend/snapAI-backend/venv/lib/python3.13/site-packages/django/urls/base.py", line 25, in resolve
2025-09-27 14:51:06,340:     return get_resolver(urlconf).resolve(path)
2025-09-27 14:51:06,340:            ~~~~~~~~~~~~~~~~~~~~~~~~~~~~~^^^^^^
2025-09-27 14:51:06,340: 
2025-09-27 14:51:06,340:   File "/home/snapaibackend/snapAI-backend/venv/lib/python3.13/site-packages/django/urls/resolvers.py", line 666, in resolve
2025-09-27 14:51:06,340:     for pattern in self.url_patterns:
2025-09-27 14:51:06,340:                    ^^^^^^^^^^^^^^^^^
2025-09-27 14:51:06,340: 
2025-09-27 14:51:06,341:   File "/home/snapaibackend/snapAI-backend/venv/lib/python3.13/site-packages/django/utils/functional.py", line 47, in __get__
2025-09-27 14:51:06,341:     res = instance.__dict__[self.name] = self.func(instance)
2025-09-27 14:51:06,341:                                          ~~~~~~~~~^^^^^^^^^^
2025-09-27 14:51:06,341: 
2025-09-27 14:51:06,341:   File "/home/snapaibackend/snapAI-backend/venv/lib/python3.13/site-packages/django/urls/resolvers.py", line 718, in url_patterns
2025-09-27 14:51:06,341:     patterns = getattr(self.urlconf_module, "urlpatterns", self.urlconf_module)
2025-09-27 14:51:06,341:                        ^^^^^^^^^^^^^^^^^^^
2025-09-27 14:51:06,341: 
2025-09-27 14:51:06,342:   File "/home/snapaibackend/snapAI-backend/venv/lib/python3.13/site-packages/django/utils/functional.py", line 47, in __get__
2025-09-27 14:51:06,342:     res = instance.__dict__[self.name] = self.func(instance)
2025-09-27 14:51:06,342:                                          ~~~~~~~~~^^^^^^^^^^
2025-09-27 14:51:06,343: 
2025-09-27 14:51:06,343:   File "/home/snapaibackend/snapAI-backend/venv/lib/python3.13/site-packages/django/urls/resolvers.py", line 711, in urlconf_module
2025-09-27 14:51:06,343:     return import_module(self.urlconf_name)
2025-09-27 14:51:06,343: 
2025-09-27 14:51:06,343:   File "/home/snapaibackend/snapAI-backend/snapAI/urls.py", line 5, in <module>
2025-09-27 14:51:06,344:     path("api/", include("api.urls")),  # твои API-роуты
2025-09-27 14:51:06,344:                  ~~~~~~~^^^^^^^^^^^^
2025-09-27 14:51:06,344: 
2025-09-27 14:51:06,344:   File "/home/snapaibackend/snapAI-backend/venv/lib/python3.13/site-packages/django/urls/conf.py", line 39, in include
2025-09-27 14:51:06,344:     urlconf_module = import_module(urlconf_module)
2025-09-27 14:51:06,344: 
2025-09-27 14:51:06,344:   File "/home/snapaibackend/snapAI-backend/api/urls.py", line 6, in <module>
2025-09-27 14:51:06,345:     from .views_auth_social import GoogleLoginView, AppleLoginView
2025-09-27 14:51:06,345: 
2025-09-27 14:51:06,345:   File "/home/snapaibackend/snapAI-backend/api/views_auth_social.py", line 12, in <module>
2025-09-27 14:51:06,345:     from .services.social_verify import verify_google_id_token, verify_apple_id_token
2025-09-27 14:51:06,345: 
2025-09-27 14:51:06,346:   File "/home/snapaibackend/snapAI-backend/api/services/social_verify.py", line 2, in <module>
2025-09-27 14:51:06,346:     from google.oauth2 import id_token as google_id_token
2025-09-27 14:51:06,337: 
2025-09-27 14:51:06,337:   File "/home/snapaibackend/snapAI-backend/venv/lib/python3.13/site-packages/django/core/handlers/exception.py", line 182, in handle_uncaught_exception
2025-09-27 14:51:06,337:     return debug.technical_500_response(request, *exc_info)
2025-09-27 14:51:06,337:            ~~~~~~~~~~~~~~~~~~~~~~~~~~~~^^^^^^^^^^^^^^^^^^^^
2025-09-27 14:51:06,338: 
2025-09-27 14:51:06,338:   File "/home/snapaibackend/snapAI-backend/venv/lib/python3.13/site-packages/django/views/debug.py", line 69, in technical_500_response
2025-09-27 14:51:06,338:     html = reporter.get_traceback_html()
2025-09-27 14:51:16,481: ModuleNotFoundError: No module named 'google'
2025-09-27 14:51:16,482:   File "/home/snapaibackend/snapAI-backend/venv/lib/python3.13/site-packages/django/core/handlers/wsgi.py", line 124, in __call__
2025-09-27 14:51:16,482:     response = self.get_response(request)
2025-09-27 14:51:16,482: 
2025-09-27 14:51:16,482:   File "/home/snapaibackend/snapAI-backend/venv/lib/python3.13/site-packages/django/core/handlers/base.py", line 140, in get_response
2025-09-27 14:51:16,482:     response = self._middleware_chain(request)
2025-09-27 14:51:16,482: 
2025-09-27 14:51:16,482:   File "/home/snapaibackend/snapAI-backend/venv/lib/python3.13/site-packages/django/core/handlers/exception.py", line 57, in inner
2025-09-27 14:51:16,483:     response = response_for_exception(request, exc)
2025-09-27 14:51:16,483: 
2025-09-27 14:51:16,483:   File "/home/snapaibackend/snapAI-backend/venv/lib/python3.13/site-packages/django/core/handlers/exception.py", line 141, in response_for_exception
2025-09-27 14:51:16,483:     response = handle_uncaught_exception(
2025-09-27 14:51:16,483:         request, get_resolver(get_urlconf()), sys.exc_info()
2025-09-27 14:51:16,483:     )
2025-09-27 14:51:16,483: 
2025-09-27 14:51:16,483:   File "/home/snapaibackend/snapAI-backend/venv/lib/python3.13/site-packages/django/core/handlers/exception.py", line 182, in handle_uncaught_exception
2025-09-27 14:51:16,484:     return debug.technical_500_response(request, *exc_info)
2025-09-27 14:51:16,484:            ~~~~~~~~~~~~~~~~~~~~~~~~~~~~^^^^^^^^^^^^^^^^^^^^
2025-09-27 14:51:16,484: 
2025-09-27 14:51:16,484:   File "/home/snapaibackend/snapAI-backend/venv/lib/python3.13/site-packages/django/views/debug.py", line 69, in technical_500_response
2025-09-27 14:51:16,484:     html = reporter.get_traceback_html()
2025-09-27 14:51:16,484: 
2025-09-27 14:51:16,484:   File "/home/snapaibackend/snapAI-backend/venv/lib/python3.13/site-packages/django/views/debug.py", line 428, in get_traceback_html
2025-09-27 14:51:16,484:     c = Context(self.get_traceback_data(), use_l10n=False)
2025-09-27 14:51:16,485:                 ~~~~~~~~~~~~~~~~~~~~~~~^^
2025-09-27 14:51:16,485: 
2025-09-27 14:51:16,485:   File "/home/snapaibackend/snapAI-backend/venv/lib/python3.13/site-packages/django/views/debug.py", line 411, in get_traceback_data
2025-09-27 14:51:16,485:     c["raising_view_name"] = get_caller(self.request)
2025-09-27 14:51:16,485:                              ~~~~~~~~~~^^^^^^^^^^^^^^
2025-09-27 14:51:16,485: 
2025-09-27 14:51:16,485:   File "/home/snapaibackend/snapAI-backend/venv/lib/python3.13/site-packages/django/views/debug.py", line 102, in get_caller
2025-09-27 14:51:16,485:     resolver_match = resolve(request.path)
2025-09-27 14:51:16,486: 
2025-09-27 14:51:16,486:   File "/home/snapaibackend/snapAI-backend/venv/lib/python3.13/site-packages/django/urls/base.py", line 25, in resolve
2025-09-27 14:51:16,486:     return get_resolver(urlconf).resolve(path)
2025-09-27 14:51:16,486:            ~~~~~~~~~~~~~~~~~~~~~~~~~~~~~^^^^^^
2025-09-27 14:51:16,486: 
2025-09-27 14:51:16,486:   File "/home/snapaibackend/snapAI-backend/venv/lib/python3.13/site-packages/django/urls/resolvers.py", line 666, in resolve
2025-09-27 14:51:16,486:     for pattern in self.url_patterns:
2025-09-27 14:51:16,486:                    ^^^^^^^^^^^^^^^^^
2025-09-27 14:51:16,486: 
2025-09-27 14:51:16,487:   File "/home/snapaibackend/snapAI-backend/venv/lib/python3.13/site-packages/django/utils/functional.py", line 47, in __get__
2025-09-27 14:51:16,487:     res = instance.__dict__[self.name] = self.func(instance)
2025-09-27 14:51:16,487:                                          ~~~~~~~~~^^^^^^^^^^
2025-09-27 14:51:16,487: 
2025-09-27 14:51:16,487:   File "/home/snapaibackend/snapAI-backend/venv/lib/python3.13/site-packages/django/urls/resolvers.py", line 718, in url_patterns
2025-09-27 14:51:16,487:     patterns = getattr(self.urlconf_module, "urlpatterns", self.urlconf_module)
2025-09-27 14:51:16,487:                        ^^^^^^^^^^^^^^^^^^^
2025-09-27 14:51:16,487: 
2025-09-27 14:51:16,488:   File "/home/snapaibackend/snapAI-backend/venv/lib/python3.13/site-packages/django/utils/functional.py", line 47, in __get__
2025-09-27 14:51:16,488:     res = instance.__dict__[self.name] = self.func(instance)
2025-09-27 14:51:16,488:                                          ~~~~~~~~~^^^^^^^^^^
2025-09-27 14:51:16,488: 
2025-09-27 14:51:16,490:   File "/home/snapaibackend/snapAI-backend/venv/lib/python3.13/site-packages/django/urls/resolvers.py", line 711, in urlconf_module
2025-09-27 14:51:16,490:     return import_module(self.urlconf_name)
2025-09-27 14:51:16,490: 
2025-09-27 14:51:16,490:   File "/home/snapaibackend/snapAI-backend/snapAI/urls.py", line 5, in <module>
2025-09-27 14:51:16,490:     path("api/", include("api.urls")),  # твои API-роуты
2025-09-27 14:51:16,491:                  ~~~~~~~^^^^^^^^^^^^
2025-09-27 14:51:16,491: 
2025-09-27 14:51:16,491:   File "/home/snapaibackend/snapAI-backend/venv/lib/python3.13/site-packages/django/urls/conf.py", line 39, in include
2025-09-27 14:51:16,491:     urlconf_module = import_module(urlconf_module)
2025-09-27 14:51:16,491: 
2025-09-27 14:51:16,491:   File "/home/snapaibackend/snapAI-backend/api/urls.py", line 6, in <module>
2025-09-27 14:51:16,491:     from .views_auth_social import GoogleLoginView, AppleLoginView
2025-09-27 14:51:16,492: 
2025-09-27 14:51:16,492:   File "/home/snapaibackend/snapAI-backend/api/views_auth_social.py", line 12, in <module>
2025-09-27 14:51:16,492:     from .services.social_verify import verify_google_id_token, verify_apple_id_token
2025-09-27 14:51:16,492: 
2025-09-27 14:51:16,492:   File "/home/snapaibackend/snapAI-backend/api/services/social_verify.py", line 2, in <module>
2025-09-27 14:51:16,492:     from google.oauth2 import id_token as google_id_token
2025-09-27 14:51:16,462: Error running WSGI application
2025-09-27 14:51:24,108: Error running WSGI application
2025-09-27 14:51:24,135:   File "/home/snapaibackend/snapAI-backend/venv/lib/python3.13/site-packages/django/urls/resolvers.py", line 666, in resolve
2025-09-27 14:51:24,135:     for pattern in self.url_patterns:
2025-09-27 14:51:24,135:                    ^^^^^^^^^^^^^^^^^
2025-09-27 14:51:24,137: 
2025-09-27 14:51:24,137:   File "/home/snapaibackend/snapAI-backend/venv/lib/python3.13/site-packages/django/utils/functional.py", line 47, in __get__
2025-09-27 14:51:24,138:     res = instance.__dict__[self.name] = self.func(instance)
2025-09-27 14:51:24,138: 
2025-09-27 14:51:24,138:   File "/home/snapaibackend/snapAI-backend/venv/lib/python3.13/site-packages/django/urls/resolvers.py", line 718, in url_patterns
2025-09-27 14:51:24,138:     patterns = getattr(self.urlconf_module, "urlpatterns", self.urlconf_module)
2025-09-27 14:51:24,139:                        ^^^^^^^^^^^^^^^^^^^
2025-09-27 14:51:24,139: 
2025-09-27 14:51:24,139:   File "/home/snapaibackend/snapAI-backend/venv/lib/python3.13/site-packages/django/utils/functional.py", line 47, in __get__
2025-09-27 14:51:24,139:     res = instance.__dict__[self.name] = self.func(instance)
2025-09-27 14:51:24,139:                                          ~~~~~~~~~^^^^^^^^^^
2025-09-27 14:51:24,140: 
2025-09-27 14:51:24,140:   File "/home/snapaibackend/snapAI-backend/venv/lib/python3.13/site-packages/django/urls/resolvers.py", line 711, in urlconf_module
2025-09-27 14:51:24,140:     return import_module(self.urlconf_name)
2025-09-27 14:51:24,140: 
2025-09-27 14:51:24,140:   File "/home/snapaibackend/snapAI-backend/snapAI/urls.py", line 5, in <module>
2025-09-27 14:51:24,141:     path("api/", include("api.urls")),  # твои API-роуты
2025-09-27 14:51:24,141:                  ~~~~~~~^^^^^^^^^^^^
2025-09-27 14:51:24,141: 
2025-09-27 14:51:24,142:   File "/home/snapaibackend/snapAI-backend/venv/lib/python3.13/site-packages/django/urls/conf.py", line 39, in include
2025-09-27 14:51:24,142:     urlconf_module = import_module(urlconf_module)
2025-09-27 14:51:24,142: 
2025-09-27 14:51:24,142:   File "/home/snapaibackend/snapAI-backend/api/urls.py", line 6, in <module>
2025-09-27 14:51:24,142:     from .views_auth_social import GoogleLoginView, AppleLoginView
2025-09-27 14:51:24,143: 
2025-09-27 14:51:24,143:   File "/home/snapaibackend/snapAI-backend/api/views_auth_social.py", line 12, in <module>
2025-09-27 14:51:24,143:     from .services.social_verify import verify_google_id_token, verify_apple_id_token
2025-09-27 14:51:24,143: 
2025-09-27 14:51:24,143:   File "/home/snapaibackend/snapAI-backend/api/services/social_verify.py", line 2, in <module>
2025-09-27 14:51:24,127: ModuleNotFoundError: No module named 'google'
2025-09-27 14:51:24,128:   File "/home/snapaibackend/snapAI-backend/venv/lib/python3.13/site-packages/django/core/handlers/wsgi.py", line 124, in __call__
2025-09-27 14:51:24,128:     response = self.get_response(request)
2025-09-27 14:51:24,128: 
2025-09-27 14:51:24,128:   File "/home/snapaibackend/snapAI-backend/venv/lib/python3.13/site-packages/django/core/handlers/base.py", line 140, in get_response
2025-09-27 14:51:24,128:     response = self._middleware_chain(request)
2025-09-27 14:51:24,129: 
2025-09-27 14:51:24,129:   File "/home/snapaibackend/snapAI-backend/venv/lib/python3.13/site-packages/django/core/handlers/exception.py", line 57, in inner
2025-09-27 14:51:24,129:     response = response_for_exception(request, exc)
2025-09-27 14:51:24,129: 
2025-09-27 14:51:24,129:   File "/home/snapaibackend/snapAI-backend/venv/lib/python3.13/site-packages/django/core/handlers/exception.py", line 141, in response_for_exception
2025-09-27 14:51:24,130:     response = handle_uncaught_exception(
2025-09-27 14:51:24,130:         request, get_resolver(get_urlconf()), sys.exc_info()
2025-09-27 14:51:24,130:     )
2025-09-27 14:51:24,130: 
2025-09-27 14:51:24,130:   File "/home/snapaibackend/snapAI-backend/venv/lib/python3.13/site-packages/django/core/handlers/exception.py", line 182, in handle_uncaught_exception
2025-09-27 14:51:24,130:     return debug.technical_500_response(request, *exc_info)
2025-09-27 14:51:24,131:            ~~~~~~~~~~~~~~~~~~~~~~~~~~~~^^^^^^^^^^^^^^^^^^^^
2025-09-27 14:51:24,131: 
2025-09-27 14:51:24,131:   File "/home/snapaibackend/snapAI-backend/venv/lib/python3.13/site-packages/django/views/debug.py", line 69, in technical_500_response
2025-09-27 14:51:24,131:     html = reporter.get_traceback_html()
2025-09-27 14:51:24,131: 
2025-09-27 14:51:24,132:   File "/home/snapaibackend/snapAI-backend/venv/lib/python3.13/site-packages/django/views/debug.py", line 428, in get_traceback_html
2025-09-27 14:51:24,132:     c = Context(self.get_traceback_data(), use_l10n=False)
2025-09-27 14:51:24,132:                 ~~~~~~~~~~~~~~~~~~~~~~~^^
2025-09-27 14:51:24,132: 
2025-09-27 14:51:24,132:   File "/home/snapaibackend/snapAI-backend/venv/lib/python3.13/site-packages/django/views/debug.py", line 411, in get_traceback_data
2025-09-27 14:51:24,133:     c["raising_view_name"] = get_caller(self.request)
2025-09-27 14:51:24,133:                              ~~~~~~~~~~^^^^^^^^^^^^^^
2025-09-27 14:51:24,133: 
2025-09-27 14:51:24,133:   File "/home/snapaibackend/snapAI-backend/venv/lib/python3.13/site-packages/django/views/debug.py", line 102, in get_caller
2025-09-27 14:51:24,133:     resolver_match = resolve(request.path)
2025-09-27 14:51:24,134: 
2025-09-27 14:51:24,134:   File "/home/snapaibackend/snapAI-backend/venv/lib/python3.13/site-packages/django/urls/base.py", line 25, in resolve
2025-09-27 14:51:24,134:     return get_resolver(urlconf).resolve(path)
2025-09-27 14:51:24,134:            ~~~~~~~~~~~~~~~~~~~~~~~~~~~~~^^^^^^
2025-09-27 14:51:24,134: 
2025-09-27 14:51:24,144:     from google.oauth2 import id_token as google_id_token